Workbook

Sheet СВОД
B3: ИТОГО ПРОЕКТ "НАЗВАНИЕ" | C3: ИТОГО | D3: ПРОДАНО | E3: ОСТАТОК К ПРОДАЖЕ | G3: 2025 | H3: 2026 | I3: 2027 | J3: 2028 | K3: 2029 | L3: 2030 | M3: 2031 | N3: 2032 | O3: 2033 | Q3: 1 кв. 2025 | R3: 2 кв. 2025 | S3: 3 кв. 2025 | T3: 4 кв. 2025 | U3: 1 кв. 2026 | V3: 2 кв. 2026 | W3: 3 кв. 2026 | X3: 4 кв. 2026 | Y3: 1 кв. 2027 | Z3: 2 кв. 2027 | AA3: 3 кв. 2027 | AB3: 4 кв. 2027 | AC3: 1 кв. 2028 | AD3: 2 кв. 2028 | AE3: 3 кв. 2028 | AF3: 4 кв. 2028 | AG3: 1 кв. 2029 | AH3: 2 кв. 2029 | AI3: 3 кв. 2029 | AJ3: 4 кв. 2029 | AK3: 1 кв. 2030 | AL3: 2 кв. 2030 | AM3: 3 кв. 2030 | AN3: 4 кв. 2030 | AO3: 1 кв. 2031 | AP3: 2 кв. 2031 | AQ3: 3 кв. 2031 | AR3: 4 кв. 2031 | AS3: 1 кв. 2032 | AT3: 2 кв. 2032 | AU3: 3 кв. 2032 | AV3: 4 кв. 2032 | AW3: 1 кв. 2033 | AX3: 2 кв. 2033 | AY3: 3 кв. 2033 | AZ3: 4 кв. 2033 | BB3: 45658 | BC3: 45689 | BD3: 45717 | BE3: 45748 | BF3: 45778 | BG3: 45809 | BH3: 45839 | BI3: 45870 | BJ3: 45901 | BK3: 45931 | BL3: 45962 | BM3: 45992 | BN3: 46023 | BO3: 46054 | BP3: 46082 | BQ3: 46113 | BR3: 46143 | BS3: 46174 | BT3: 46204 | BU3: 46235 | BV3: 46266 | BW3: 46296 | BX3: 46327 | BY3: 46357 | BZ3: 46388 | CA3: 46419 | CB3: 46447 | CC3: 46478 | CD3: 46508 | CE3: 46539 | CF3: 46569 | CG3: 46600 | CH3: 46631 | CI3: 46661 | CJ3: 46692 | CK3: 46722 | CL3: 46753 | CM3: 46784 | CN3: 46813 | CO3: 46844 | CP3: 46874 | CQ3: 46905 | CR3: 46935 | CS3: 46966 | CT3: 46997 | CU3: 47027 | CV3: 47058 | CW3: 47088 | CX3: 47119 | CY3: 47150 | CZ3: 47178 | DA3: 47209 | DB3: 47239 | DC3: 47270 | DD3: 47300 | DE3: 47331 | DF3: 47362 | DG3: 47392 | DH3: 47423 | DI3: 47453 | DJ3: 47484 | DK3: 47515 | DL3: 47543 | DM3: 47574 | DN3: 47604 | DO3: 47635 | DP3: 47665 | DQ3: 47696 | DR3: 47727 | DS3: 47757 | DT3: 47788 | DU3: 47818 | DV3: 47849 | DW3: 47880 | DX3: 47908 | DY3: 47939 | DZ3: 47969 | EA3: 48000 | EB3: 48030 | EC3: 48061 | ED3: 48092 | EE3: 48122 | EF3: 48153 | EG3: 48183 | EH3: 48214 | EI3: 48245 | EJ3: 48274 | EK3: 48305 | EL3: 48335 | EM3: 48366 | EN3: 48396 | EO3: 48427 | EP3: 48458 | EQ3: 48488 | ER3: 48519 | ES3: 48549 | ET3: 48580 | EU3: 48611 | EV3: 48639 | EW3: 48670 | EX3: 48700 | EY3: 48731 | EZ3: 48761 | FA3: 48792 | FB3: 48823 | FC3: 48853 | FD3: 48884 | FE3: 48914
B4: Продажи, руб. | C4: =SUM(C10,C17,C24,C31,C38) -> 0 | D4: =SUM(D10,D17,D24,D31,D38) -> 0 | E4: =SUM(E10,E17,E24,E31,E38) -> 0 | G4: =SUM(G10,G17,G24,G31,G38) -> 0 | H4: =SUM(H10,H17,H24,H31,H38) -> 0 | I4: =SUM(I10,I17,I24,I31,I38) -> 0 | J4: =SUM(J10,J17,J24,J31,J38) -> 0 | K4: =SUM(K10,K17,K24,K31,K38) -> 0 | L4: =SUM(L10,L17,L24,L31,L38) -> 0 | M4: =SUM(M10,M17,M24,M31,M38) -> 0 | N4: =SUM(N10,N17,N24,N31,N38) -> 0 | O4: =SUM(O10,O17,O24,O31,O38) -> 0 | Q4: =SUM(Q10,Q17,Q24,Q31,Q38) -> 0 | R4: =SUM(R10,R17,R24,R31,R38) -> 0 | S4: =SUM(S10,S17,S24,S31,S38) -> 0 | T4: =SUM(T10,T17,T24,T31,T38) -> 0 | U4: =SUM(U10,U17,U24,U31,U38) -> 0 | V4: =SUM(V10,V17,V24,V31,V38) -> 0 | W4: =SUM(W10,W17,W24,W31,W38) -> 0 | X4: =SUM(X10,X17,X24,X31,X38) -> 0 | ... AZ4: =SUM(AZ10,AZ17,AZ24,AZ31,AZ38) -> 0 | BB4: =SUM(BB10,BB17,BB24,BB31,BB38) -> 0 | BC4: =SUM(BC10,BC17,BC24,BC31,BC38) -> 0 | BD4: =SUM(BD10,BD17,BD24,BD31,BD38) -> 0 | BE4: =SUM(BE10,BE17,BE24,BE31,BE38) -> 0 | BF4: =SUM(BF10,BF17,BF24,BF31,BF38) -> 0 | BG4: =SUM(BG10,BG17,BG24,BG31,BG38) -> 0 | BH4: =SUM(BH10,BH17,BH24,BH31,BH38) -> 0 | BI4: =SUM(BI10,BI17,BI24,BI31,BI38) -> 0 | ... FE4: =SUM(FE10,FE17,FE24,FE31,FE38) -> 0
B5: Поступление ден. средств, руб. | C5: =SUM(C14,C21,C28,C35,C41) -> 0 | D5: =SUM(D14,D21,D28,D35,D41) -> 0 | E5: =SUM(E14,E21,E28,E35,E41) -> 0 | G5: =SUM(G14,G21,G28,G35,G41) -> 0 | H5: =SUM(H14,H21,H28,H35,H41) -> 0 | I5: =SUM(I14,I21,I28,I35,I41) -> 0 | J5: =SUM(J14,J21,J28,J35,J41) -> 0 | K5: =SUM(K14,K21,K28,K35,K41) -> 0 | L5: =SUM(L14,L21,L28,L35,L41) -> 0 | M5: =SUM(M14,M21,M28,M35,M41) -> 0 | N5: =SUM(N14,N21,N28,N35,N41) -> 0 | O5: =SUM(O14,O21,O28,O35,O41) -> 0 | Q5: =SUM(Q14,Q21,Q28,Q35,Q41) -> 0 | R5: =SUM(R14,R21,R28,R35,R41) -> 0 | S5: =SUM(S14,S21,S28,S35,S41) -> 0 | T5: =SUM(T14,T21,T28,T35,T41) -> 0 | U5: =SUM(U14,U21,U28,U35,U41) -> 0 | V5: =SUM(V14,V21,V28,V35,V41) -> 0 | W5: =SUM(W14,W21,W28,W35,W41) -> 0 | X5: =SUM(X14,X21,X28,X35,X41) -> 0 | ... AZ5: =SUM(AZ14,AZ21,AZ28,AZ35,AZ41) -> 0 | BB5: =SUM(BB14,BB21,BB28,BB35,BB41) -> 0 | BC5: =SUM(BC14,BC21,BC28,BC35,BC41) -> 0 | BD5: =SUM(BD14,BD21,BD28,BD35,BD41) -> 0 | BE5: =SUM(BE14,BE21,BE28,BE35,BE41) -> 0 | BF5: =SUM(BF14,BF21,BF28,BF35,BF41) -> 0 | BG5: =SUM(BG14,BG21,BG28,BG35,BG41) -> 0 | BH5: =SUM(BH14,BH21,BH28,BH35,BH41) -> 0 | BI5: =SUM(BI14,BI21,BI28,BI35,BI41) -> 0 | ... FE5: =SUM(FE14,FE21,FE28,FE35,FE41) -> 0
B9: ЖИЛЬЕ | C9: ИТОГО | D9: ПРОДАНО | E9: ОСТАТОК К ПРОДАЖЕ | G9: 2025 | H9: 2026 | I9: 2027 | J9: 2028 | K9: 2029 | L9: 2030 | M9: 2031 | N9: 2032 | O9: 2033 | Q9: 1 кв. 2025 | R9: 2 кв. 2025 | S9: 3 кв. 2025 | T9: 4 кв. 2025 | U9: 1 кв. 2026 | V9: 2 кв. 2026 | W9: 3 кв. 2026 | X9: 4 кв. 2026 | Y9: 1 кв. 2027 | Z9: 2 кв. 2027 | AA9: 3 кв. 2027 | AB9: 4 кв. 2027 | AC9: 1 кв. 2028 | AD9: 2 кв. 2028 | AE9: 3 кв. 2028 | AF9: 4 кв. 2028 | AG9: 1 кв. 2029 | AH9: 2 кв. 2029 | AI9: 3 кв. 2029 | AJ9: 4 кв. 2029 | AK9: 1 кв. 2030 | AL9: 2 кв. 2030 | AM9: 3 кв. 2030 | AN9: 4 кв. 2030 | AO9: 1 кв. 2031 | AP9: 2 кв. 2031 | AQ9: 3 кв. 2031 | AR9: 4 кв. 2031 | AS9: 1 кв. 2032 | AT9: 2 кв. 2032 | AU9: 3 кв. 2032 | AV9: 4 кв. 2032 | AW9: 1 кв. 2033 | AX9: 2 кв. 2033 | AY9: 3 кв. 2033 | AZ9: 4 кв. 2033 | BB9: 45658 | BC9: 45689 | BD9: 45717 | BE9: 45748 | BF9: 45778 | BG9: 45809 | BH9: 45839 | BI9: 45870 | BJ9: 45901 | BK9: 45931 | BL9: 45962 | BM9: 45992 | BN9: 46023 | BO9: 46054 | BP9: 46082 | BQ9: 46113 | BR9: 46143 | BS9: 46174 | BT9: 46204 | BU9: 46235 | BV9: 46266 | BW9: 46296 | BX9: 46327 | BY9: 46357 | BZ9: 46388 | CA9: 46419 | CB9: 46447 | CC9: 46478 | CD9: 46508 | CE9: 46539 | CF9: 46569 | CG9: 46600 | CH9: 46631 | CI9: 46661 | CJ9: 46692 | CK9: 46722 | CL9: 46753 | CM9: 46784 | CN9: 46813 | CO9: 46844 | CP9: 46874 | CQ9: 46905 | CR9: 46935 | CS9: 46966 | CT9: 46997 | CU9: 47027 | CV9: 47058 | CW9: 47088 | CX9: 47119 | CY9: 47150 | CZ9: 47178 | DA9: 47209 | DB9: 47239 | DC9: 47270 | DD9: 47300 | DE9: 47331 | DF9: 47362 | DG9: 47392 | DH9: 47423 | DI9: 47453 | DJ9: 47484 | DK9: 47515 | DL9: 47543 | DM9: 47574 | DN9: 47604 | DO9: 47635 | DP9: 47665 | DQ9: 47696 | DR9: 47727 | DS9: 47757 | DT9: 47788 | DU9: 47818 | DV9: 47849 | DW9: 47880 | DX9: 47908 | DY9: 47939 | DZ9: 47969 | EA9: 48000 | EB9: 48030 | EC9: 48061 | ED9: 48092 | EE9: 48122 | EF9: 48153 | EG9: 48183 | EH9: 48214 | EI9: 48245 | EJ9: 48274 | EK9: 48305 | EL9: 48335 | EM9: 48366 | EN9: 48396 | EO9: 48427 | EP9: 48458 | EQ9: 48488 | ER9: 48519 | ES9: 48549 | ET9: 48580 | EU9: 48611 | EV9: 48639 | EW9: 48670 | EX9: 48700 | EY9: 48731 | EZ9: 48761 | FA9: 48792 | FB9: 48823 | FC9: 48853 | FD9: 48884 | FE9: 48914
B10: Продажи, руб. | C10: =ЖИЛЬЕ!E8 -> 0 | D10: =ЖИЛЬЕ!E15 -> 0 | E10: =ЖИЛЬЕ!E22 -> 0 | G10: =ЖИЛЬЕ!G8 -> 0 | H10: =ЖИЛЬЕ!H8 -> 0 | I10: =ЖИЛЬЕ!I8 -> 0 | J10: =ЖИЛЬЕ!J8 -> 0 | K10: =ЖИЛЬЕ!K8 -> 0 | L10: =ЖИЛЬЕ!L8 -> 0 | M10: =ЖИЛЬЕ!M8 -> 0 | N10: =ЖИЛЬЕ!N8 -> 0 | O10: =ЖИЛЬЕ!O8 -> 0 | Q10: =ЖИЛЬЕ!Q8 -> 0 | R10: =ЖИЛЬЕ!R8 -> 0 | S10: =ЖИЛЬЕ!S8 -> 0 | T10: =ЖИЛЬЕ!T8 -> 0 | U10: =ЖИЛЬЕ!U8 -> 0 | V10: =ЖИЛЬЕ!V8 -> 0 | W10: =ЖИЛЬЕ!W8 -> 0 | X10: =ЖИЛЬЕ!X8 -> 0 | ... AZ10: =ЖИЛЬЕ!AZ8 -> 0 | BB10: =ЖИЛЬЕ!BB8 -> 0 | BC10: =ЖИЛЬЕ!BC8 -> 0 | BD10: =ЖИЛЬЕ!BD8 -> 0 | BE10: =ЖИЛЬЕ!BE8 -> 0 | BF10: =ЖИЛЬЕ!BF8 -> 0 | BG10: =ЖИЛЬЕ!BG8 -> 0 | BH10: =ЖИЛЬЕ!BH8 -> 0 | BI10: =ЖИЛЬЕ!BI8 -> 0 | ... FE10: =ЖИЛЬЕ!FE8 -> 0
B11: объем законтрактованных площадей, м2 | C11: =ЖИЛЬЕ!E9 -> 0 | D11: =ЖИЛЬЕ!E16 -> 0 | E11: =ЖИЛЬЕ!E23 -> 0 | G11: =ЖИЛЬЕ!G9 -> 0 | H11: =ЖИЛЬЕ!H9 -> 0 | I11: =ЖИЛЬЕ!I9 -> 0 | J11: =ЖИЛЬЕ!J9 -> 0 | K11: =ЖИЛЬЕ!K9 -> 0 | L11: =ЖИЛЬЕ!L9 -> 0 | M11: =ЖИЛЬЕ!M9 -> 0 | N11: =ЖИЛЬЕ!N9 -> 0 | O11: =ЖИЛЬЕ!O9 -> 0 | Q11: =ЖИЛЬЕ!Q9 -> 0 | R11: =ЖИЛЬЕ!R9 -> 0 | S11: =ЖИЛЬЕ!S9 -> 0 | T11: =ЖИЛЬЕ!T9 -> 0 | U11: =ЖИЛЬЕ!U9 -> 0 | V11: =ЖИЛЬЕ!V9 -> 0 | W11: =ЖИЛЬЕ!W9 -> 0 | X11: =ЖИЛЬЕ!X9 -> 0 | ... AZ11: =ЖИЛЬЕ!AZ9 -> 0 | BB11: =ЖИЛЬЕ!BB9 -> 0 | BC11: =ЖИЛЬЕ!BC9 -> 0 | BD11: =ЖИЛЬЕ!BD9 -> 0 | BE11: =ЖИЛЬЕ!BE9 -> 0 | BF11: =ЖИЛЬЕ!BF9 -> 0 | BG11: =ЖИЛЬЕ!BG9 -> 0 | BH11: =ЖИЛЬЕ!BH9 -> 0 | BI11: =ЖИЛЬЕ!BI9 -> 0 | ... FE11: =ЖИЛЬЕ!FE9 -> 0
B12: цена за 1 м2, руб. | C12: =ЖИЛЬЕ!E10 -> 0 | D12: =ЖИЛЬЕ!E17 -> 0 | E12: =ЖИЛЬЕ!E24 -> 0 | G12: =ЖИЛЬЕ!G10 -> 0 | H12: =ЖИЛЬЕ!H10 -> 0 | I12: =ЖИЛЬЕ!I10 -> 0 | J12: =ЖИЛЬЕ!J10 -> 0 | K12: =ЖИЛЬЕ!K10 -> 0 | L12: =ЖИЛЬЕ!L10 -> 0 | M12: =ЖИЛЬЕ!M10 -> 0 | N12: =ЖИЛЬЕ!N10 -> 0 | O12: =ЖИЛЬЕ!O10 -> 0 | Q12: =ЖИЛЬЕ!Q10 -> 0 | R12: =ЖИЛЬЕ!R10 -> 0 | S12: =ЖИЛЬЕ!S10 -> 0 | T12: =ЖИЛЬЕ!T10 -> 0 | U12: =ЖИЛЬЕ!U10 -> 0 | V12: =ЖИЛЬЕ!V10 -> 0 | W12: =ЖИЛЬЕ!W10 -> 0 | X12: =ЖИЛЬЕ!X10 -> 0 | ... AZ12: =ЖИЛЬЕ!AZ10 -> 0 | BB12: =ЖИЛЬЕ!BB10 -> 0 | BC12: =ЖИЛЬЕ!BC10 -> 0 | BD12: =ЖИЛЬЕ!BD10 -> 0 | BE12: =ЖИЛЬЕ!BE10 -> 0 | BF12: =ЖИЛЬЕ!BF10 -> 0 | BG12: =ЖИЛЬЕ!BG10 -> 0 | BH12: =ЖИЛЬЕ!BH10 -> 0 | BI12: =ЖИЛЬЕ!BI10 -> 0 | ... FE12: =ЖИЛЬЕ!FE10 -> 0
B13: объем законтрактованных площадей, шт | C13: =ЖИЛЬЕ!E11 -> 0 | D13: =ЖИЛЬЕ!E18 -> 0 | E13: =ЖИЛЬЕ!E25 -> 0 | G13: =ЖИЛЬЕ!G11 -> 0 | H13: =ЖИЛЬЕ!H11 -> 0 | I13: =ЖИЛЬЕ!I11 -> 0 | J13: =ЖИЛЬЕ!J11 -> 0 | K13: =ЖИЛЬЕ!K11 -> 0 | L13: =ЖИЛЬЕ!L11 -> 0 | M13: =ЖИЛЬЕ!M11 -> 0 | N13: =ЖИЛЬЕ!N11 -> 0 | O13: =ЖИЛЬЕ!O11 -> 0 | Q13: =ЖИЛЬЕ!Q11 -> 0 | R13: =ЖИЛЬЕ!R11 -> 0 | S13: =ЖИЛЬЕ!S11 -> 0 | T13: =ЖИЛЬЕ!T11 -> 0 | U13: =ЖИЛЬЕ!U11 -> 0 | V13: =ЖИЛЬЕ!V11 -> 0 | W13: =ЖИЛЬЕ!W11 -> 0 | X13: =ЖИЛЬЕ!X11 -> 0 | ... AZ13: =ЖИЛЬЕ!AZ11 -> 0 | BB13: =ЖИЛЬЕ!BB11 -> 0 | BC13: =ЖИЛЬЕ!BC11 -> 0 | BD13: =ЖИЛЬЕ!BD11 -> 0 | BE13: =ЖИЛЬЕ!BE11 -> 0 | BF13: =ЖИЛЬЕ!BF11 -> 0 | BG13: =ЖИЛЬЕ!BG11 -> 0 | BH13: =ЖИЛЬЕ!BH11 -> 0 | BI13: =ЖИЛЬЕ!BI11 -> 0 | ... FE13: =ЖИЛЬЕ!FE11 -> 0
B14: Поступление ден. средств, руб. | C14: =ЖИЛЬЕ!E12 -> 0 | D14: =ЖИЛЬЕ!E19 -> 0 | E14: =ЖИЛЬЕ!E26 -> 0 | G14: =ЖИЛЬЕ!G12 -> 0 | H14: =ЖИЛЬЕ!H12 -> 0 | I14: =ЖИЛЬЕ!I12 -> 0 | J14: =ЖИЛЬЕ!J12 -> 0 | K14: =ЖИЛЬЕ!K12 -> 0 | L14: =ЖИЛЬЕ!L12 -> 0 | M14: =ЖИЛЬЕ!M12 -> 0 | N14: =ЖИЛЬЕ!N12 -> 0 | O14: =ЖИЛЬЕ!O12 -> 0 | Q14: =ЖИЛЬЕ!Q12 -> 0 | R14: =ЖИЛЬЕ!R12 -> 0 | S14: =ЖИЛЬЕ!S12 -> 0 | T14: =ЖИЛЬЕ!T12 -> 0 | U14: =ЖИЛЬЕ!U12 -> 0 | V14: =ЖИЛЬЕ!V12 -> 0 | W14: =ЖИЛЬЕ!W12 -> 0 | X14: =ЖИЛЬЕ!X12 -> 0 | ... AZ14: =ЖИЛЬЕ!AZ12 -> 0 | BB14: =ЖИЛЬЕ!BB12 -> 0 | BC14: =ЖИЛЬЕ!BC12 -> 0 | BD14: =ЖИЛЬЕ!BD12 -> 0 | BE14: =ЖИЛЬЕ!BE12 -> 0 | BF14: =ЖИЛЬЕ!BF12 -> 0 | BG14: =ЖИЛЬЕ!BG12 -> 0 | BH14: =ЖИЛЬЕ!BH12 -> 0 | BI14: =ЖИЛЬЕ!BI12 -> 0 | ... FE14: =ЖИЛЬЕ!FE12 -> 0
B16: АПАРТАМЕНТЫ | C16: ИТОГО | D16: ПРОДАНО | E16: ОСТАТОК К ПРОДАЖЕ | G16: 2025 | H16: 2026 | I16: 2027 | J16: 2028 | K16: 2029 | L16: 2030 | M16: 2031 | N16: 2032 | O16: 2033 | Q16: 1 кв. 2025 | R16: 2 кв. 2025 | S16: 3 кв. 2025 | T16: 4 кв. 2025 | U16: 1 кв. 2026 | V16: 2 кв. 2026 | W16: 3 кв. 2026 | X16: 4 кв. 2026 | Y16: 1 кв. 2027 | Z16: 2 кв. 2027 | AA16: 3 кв. 2027 | AB16: 4 кв. 2027 | AC16: 1 кв. 2028 | AD16: 2 кв. 2028 | AE16: 3 кв. 2028 | AF16: 4 кв. 2028 | AG16: 1 кв. 2029 | AH16: 2 кв. 2029 | AI16: 3 кв. 2029 | AJ16: 4 кв. 2029 | AK16: 1 кв. 2030 | AL16: 2 кв. 2030 | AM16: 3 кв. 2030 | AN16: 4 кв. 2030 | AO16: 1 кв. 2031 | AP16: 2 кв. 2031 | AQ16: 3 кв. 2031 | AR16: 4 кв. 2031 | AS16: 1 кв. 2032 | AT16: 2 кв. 2032 | AU16: 3 кв. 2032 | AV16: 4 кв. 2032 | AW16: 1 кв. 2033 | AX16: 2 кв. 2033 | AY16: 3 кв. 2033 | AZ16: 4 кв. 2033 | BB16: 45658 | BC16: 45689 | BD16: 45717 | BE16: 45748 | BF16: 45778 | BG16: 45809 | BH16: 45839 | BI16: 45870 | BJ16: 45901 | BK16: 45931 | BL16: 45962 | BM16: 45992 | BN16: 46023 | BO16: 46054 | BP16: 46082 | BQ16: 46113 | BR16: 46143 | BS16: 46174 | BT16: 46204 | BU16: 46235 | BV16: 46266 | BW16: 46296 | BX16: 46327 | BY16: 46357 | BZ16: 46388 | CA16: 46419 | CB16: 46447 | CC16: 46478 | CD16: 46508 | CE16: 46539 | CF16: 46569 | CG16: 46600 | CH16: 46631 | CI16: 46661 | CJ16: 46692 | CK16: 46722 | CL16: 46753 | CM16: 46784 | CN16: 46813 | CO16: 46844 | CP16: 46874 | CQ16: 46905 | CR16: 46935 | CS16: 46966 | CT16: 46997 | CU16: 47027 | CV16: 47058 | CW16: 47088 | CX16: 47119 | CY16: 47150 | CZ16: 47178 | DA16: 47209 | DB16: 47239 | DC16: 47270 | DD16: 47300 | DE16: 47331 | DF16: 47362 | DG16: 47392 | DH16: 47423 | DI16: 47453 | DJ16: 47484 | DK16: 47515 | DL16: 47543 | DM16: 47574 | DN16: 47604 | DO16: 47635 | DP16: 47665 | DQ16: 47696 | DR16: 47727 | DS16: 47757 | DT16: 47788 | DU16: 47818 | DV16: 47849 | DW16: 47880 | DX16: 47908 | DY16: 47939 | DZ16: 47969 | EA16: 48000 | EB16: 48030 | EC16: 48061 | ED16: 48092 | EE16: 48122 | EF16: 48153 | EG16: 48183 | EH16: 48214 | EI16: 48245 | EJ16: 48274 | EK16: 48305 | EL16: 48335 | EM16: 48366 | EN16: 48396 | EO16: 48427 | EP16: 48458 | EQ16: 48488 | ER16: 48519 | ES16: 48549 | ET16: 48580 | EU16: 48611 | EV16: 48639 | EW16: 48670 | EX16: 48700 | EY16: 48731 | EZ16: 48761 | FA16: 48792 | FB16: 48823 | FC16: 48853 | FD16: 48884 | FE16: 48914
B17: Продажи, руб. | C17: =АПАРТЫ!E8 -> 0 | D17: =АПАРТЫ!E15 -> 0 | E17: =АПАРТЫ!E22 -> 0 | G17: =АПАРТЫ!G8 -> 0 | H17: =АПАРТЫ!H8 -> 0 | I17: =АПАРТЫ!I8 -> 0 | J17: =АПАРТЫ!J8 -> 0 | K17: =АПАРТЫ!K8 -> 0 | L17: =АПАРТЫ!L8 -> 0 | M17: =АПАРТЫ!M8 -> 0 | N17: =АПАРТЫ!N8 -> 0 | O17: =АПАРТЫ!O8 -> 0 | Q17: =АПАРТЫ!Q8 -> 0 | R17: =АПАРТЫ!R8 -> 0 | S17: =АПАРТЫ!S8 -> 0 | T17: =АПАРТЫ!T8 -> 0 | U17: =АПАРТЫ!U8 -> 0 | V17: =АПАРТЫ!V8 -> 0 | W17: =АПАРТЫ!W8 -> 0 | X17: =АПАРТЫ!X8 -> 0 | ... AZ17: =АПАРТЫ!AZ8 -> 0 | BB17: =АПАРТЫ!BB8 -> 0 | BC17: =АПАРТЫ!BC8 -> 0 | BD17: =АПАРТЫ!BD8 -> 0 | BE17: =АПАРТЫ!BE8 -> 0 | BF17: =АПАРТЫ!BF8 -> 0 | BG17: =АПАРТЫ!BG8 -> 0 | BH17: =АПАРТЫ!BH8 -> 0 | BI17: =АПАРТЫ!BI8 -> 0 | ... FE17: =АПАРТЫ!FE8 -> 0
B18: объем законтрактованных площадей, м2 | C18: =АПАРТЫ!E9 -> 0 | D18: =АПАРТЫ!E16 -> 0 | E18: =АПАРТЫ!E23 -> 0 | G18: =АПАРТЫ!G9 -> 0 | H18: =АПАРТЫ!H9 -> 0 | I18: =АПАРТЫ!I9 -> 0 | J18: =АПАРТЫ!J9 -> 0 | K18: =АПАРТЫ!K9 -> 0 | L18: =АПАРТЫ!L9 -> 0 | M18: =АПАРТЫ!M9 -> 0 | N18: =АПАРТЫ!N9 -> 0 | O18: =АПАРТЫ!O9 -> 0 | Q18: =АПАРТЫ!Q9 -> 0 | R18: =АПАРТЫ!R9 -> 0 | S18: =АПАРТЫ!S9 -> 0 | T18: =АПАРТЫ!T9 -> 0 | U18: =АПАРТЫ!U9 -> 0 | V18: =АПАРТЫ!V9 -> 0 | W18: =АПАРТЫ!W9 -> 0 | X18: =АПАРТЫ!X9 -> 0 | ... AZ18: =АПАРТЫ!AZ9 -> 0 | BB18: =АПАРТЫ!BB9 -> 0 | BC18: =АПАРТЫ!BC9 -> 0 | BD18: =АПАРТЫ!BD9 -> 0 | BE18: =АПАРТЫ!BE9 -> 0 | BF18: =АПАРТЫ!BF9 -> 0 | BG18: =АПАРТЫ!BG9 -> 0 | BH18: =АПАРТЫ!BH9 -> 0 | BI18: =АПАРТЫ!BI9 -> 0 | ... FE18: =АПАРТЫ!FE9 -> 0
B19: цена за 1 м2, руб. | C19: =АПАРТЫ!E10 -> 0 | D19: =АПАРТЫ!E17 -> 0 | E19: =АПАРТЫ!E24 -> 0 | G19: =АПАРТЫ!G10 -> 0 | H19: =АПАРТЫ!H10 -> 0 | I19: =АПАРТЫ!I10 -> 0 | J19: =АПАРТЫ!J10 -> 0 | K19: =АПАРТЫ!K10 -> 0 | L19: =АПАРТЫ!L10 -> 0 | M19: =АПАРТЫ!M10 -> 0 | N19: =АПАРТЫ!N10 -> 0 | O19: =АПАРТЫ!O10 -> 0 | Q19: =АПАРТЫ!Q10 -> 0 | R19: =АПАРТЫ!R10 -> 0 | S19: =АПАРТЫ!S10 -> 0 | T19: =АПАРТЫ!T10 -> 0 | U19: =АПАРТЫ!U10 -> 0 | V19: =АПАРТЫ!V10 -> 0 | W19: =АПАРТЫ!W10 -> 0 | X19: =АПАРТЫ!X10 -> 0 | ... AZ19: =АПАРТЫ!AZ10 -> 0 | BB19: =АПАРТЫ!BB10 -> 0 | BC19: =АПАРТЫ!BC10 -> 0 | BD19: =АПАРТЫ!BD10 -> 0 | BE19: =АПАРТЫ!BE10 -> 0 | BF19: =АПАРТЫ!BF10 -> 0 | BG19: =АПАРТЫ!BG10 -> 0 | BH19: =АПАРТЫ!BH10 -> 0 | BI19: =АПАРТЫ!BI10 -> 0 | ... FE19: =АПАРТЫ!FE10 -> 0
B20: объем законтрактованных площадей, шт | C20: =АПАРТЫ!E11 -> 0 | D20: =АПАРТЫ!E18 -> 0 | E20: =АПАРТЫ!E25 -> 0 | G20: =АПАРТЫ!G11 -> 0 | H20: =АПАРТЫ!H11 -> 0 | I20: =АПАРТЫ!I11 -> 0 | J20: =АПАРТЫ!J11 -> 0 | K20: =АПАРТЫ!K11 -> 0 | L20: =АПАРТЫ!L11 -> 0 | M20: =АПАРТЫ!M11 -> 0 | N20: =АПАРТЫ!N11 -> 0 | O20: =АПАРТЫ!O11 -> 0 | Q20: =АПАРТЫ!Q11 -> 0 | R20: =АПАРТЫ!R11 -> 0 | S20: =АПАРТЫ!S11 -> 0 | T20: =АПАРТЫ!T11 -> 0 | U20: =АПАРТЫ!U11 -> 0 | V20: =АПАРТЫ!V11 -> 0 | W20: =АПАРТЫ!W11 -> 0 | X20: =АПАРТЫ!X11 -> 0 | ... AZ20: =АПАРТЫ!AZ11 -> 0 | BB20: =АПАРТЫ!BB11 -> 0 | BC20: =АПАРТЫ!BC11 -> 0 | BD20: =АПАРТЫ!BD11 -> 0 | BE20: =АПАРТЫ!BE11 -> 0 | BF20: =АПАРТЫ!BF11 -> 0 | BG20: =АПАРТЫ!BG11 -> 0 | BH20: =АПАРТЫ!BH11 -> 0 | BI20: =АПАРТЫ!BI11 -> 0 | ... FE20: =АПАРТЫ!FE11 -> 0
B21: Поступление ден. средств, руб. | C21: =АПАРТЫ!E12 -> 0 | D21: =АПАРТЫ!E19 -> 0 | E21: =АПАРТЫ!E26 -> 0 | G21: =АПАРТЫ!G12 -> 0 | H21: =АПАРТЫ!H12 -> 0 | I21: =АПАРТЫ!I12 -> 0 | J21: =АПАРТЫ!J12 -> 0 | K21: =АПАРТЫ!K12 -> 0 | L21: =АПАРТЫ!L12 -> 0 | M21: =АПАРТЫ!M12 -> 0 | N21: =АПАРТЫ!N12 -> 0 | O21: =АПАРТЫ!O12 -> 0 | Q21: =АПАРТЫ!Q12 -> 0 | R21: =АПАРТЫ!R12 -> 0 | S21: =АПАРТЫ!S12 -> 0 | T21: =АПАРТЫ!T12 -> 0 | U21: =АПАРТЫ!U12 -> 0 | V21: =АПАРТЫ!V12 -> 0 | W21: =АПАРТЫ!W12 -> 0 | X21: =АПАРТЫ!X12 -> 0 | ... AZ21: =АПАРТЫ!AZ12 -> 0 | BB21: =АПАРТЫ!BB12 -> 0 | BC21: =АПАРТЫ!BC12 -> 0 | BD21: =АПАРТЫ!BD12 -> 0 | BE21: =АПАРТЫ!BE12 -> 0 | BF21: =АПАРТЫ!BF12 -> 0 | BG21: =АПАРТЫ!BG12 -> 0 | BH21: =АПАРТЫ!BH12 -> 0 | BI21: =АПАРТЫ!BI12 -> 0 | ... FE21: =АПАРТЫ!FE12 -> 0
B23: КОММЕРЧЕСКИЕ ПОМЕЩЕНИЯ | C23: ИТОГО | D23: ПРОДАНО | E23: ОСТАТОК К ПРОДАЖЕ | G23: 2025 | H23: 2026 | I23: 2027 | J23: 2028 | K23: 2029 | L23: 2030 | M23: 2031 | N23: 2032 | O23: 2033 | Q23: 1 кв. 2025 | R23: 2 кв. 2025 | S23: 3 кв. 2025 | T23: 4 кв. 2025 | U23: 1 кв. 2026 | V23: 2 кв. 2026 | W23: 3 кв. 2026 | X23: 4 кв. 2026 | Y23: 1 кв. 2027 | Z23: 2 кв. 2027 | AA23: 3 кв. 2027 | AB23: 4 кв. 2027 | AC23: 1 кв. 2028 | AD23: 2 кв. 2028 | AE23: 3 кв. 2028 | AF23: 4 кв. 2028 | AG23: 1 кв. 2029 | AH23: 2 кв. 2029 | AI23: 3 кв. 2029 | AJ23: 4 кв. 2029 | AK23: 1 кв. 2030 | AL23: 2 кв. 2030 | AM23: 3 кв. 2030 | AN23: 4 кв. 2030 | AO23: 1 кв. 2031 | AP23: 2 кв. 2031 | AQ23: 3 кв. 2031 | AR23: 4 кв. 2031 | AS23: 1 кв. 2032 | AT23: 2 кв. 2032 | AU23: 3 кв. 2032 | AV23: 4 кв. 2032 | AW23: 1 кв. 2033 | AX23: 2 кв. 2033 | AY23: 3 кв. 2033 | AZ23: 4 кв. 2033 | BB23: 45658 | BC23: 45689 | BD23: 45717 | BE23: 45748 | BF23: 45778 | BG23: 45809 | BH23: 45839 | BI23: 45870 | BJ23: 45901 | BK23: 45931 | BL23: 45962 | BM23: 45992 | BN23: 46023 | BO23: 46054 | BP23: 46082 | BQ23: 46113 | BR23: 46143 | BS23: 46174 | BT23: 46204 | BU23: 46235 | BV23: 46266 | BW23: 46296 | BX23: 46327 | BY23: 46357 | BZ23: 46388 | CA23: 46419 | CB23: 46447 | CC23: 46478 | CD23: 46508 | CE23: 46539 | CF23: 46569 | CG23: 46600 | CH23: 46631 | CI23: 46661 | CJ23: 46692 | CK23: 46722 | CL23: 46753 | CM23: 46784 | CN23: 46813 | CO23: 46844 | CP23: 46874 | CQ23: 46905 | CR23: 46935 | CS23: 46966 | CT23: 46997 | CU23: 47027 | CV23: 47058 | CW23: 47088 | CX23: 47119 | CY23: 47150 | CZ23: 47178 | DA23: 47209 | DB23: 47239 | DC23: 47270 | DD23: 47300 | DE23: 47331 | DF23: 47362 | DG23: 47392 | DH23: 47423 | DI23: 47453 | DJ23: 47484 | DK23: 47515 | DL23: 47543 | DM23: 47574 | DN23: 47604 | DO23: 47635 | DP23: 47665 | DQ23: 47696 | DR23: 47727 | DS23: 47757 | DT23: 47788 | DU23: 47818 | DV23: 47849 | DW23: 47880 | DX23: 47908 | DY23: 47939 | DZ23: 47969 | EA23: 48000 | EB23: 48030 | EC23: 48061 | ED23: 48092 | EE23: 48122 | EF23: 48153 | EG23: 48183 | EH23: 48214 | EI23: 48245 | EJ23: 48274 | EK23: 48305 | EL23: 48335 | EM23: 48366 | EN23: 48396 | EO23: 48427 | EP23: 48458 | EQ23: 48488 | ER23: 48519 | ES23: 48549 | ET23: 48580 | EU23: 48611 | EV23: 48639 | EW23: 48670 | EX23: 48700 | EY23: 48731 | EZ23: 48761 | FA23: 48792 | FB23: 48823 | FC23: 48853 | FD23: 48884 | FE23: 48914
B24: Продажи, руб. | C24: =КОММЕРЦИЯ!E8 -> 0 | D24: =КОММЕРЦИЯ!E15 -> 0 | E24: =КОММЕРЦИЯ!E22 -> 0 | G24: =КОММЕРЦИЯ!G8 -> 0 | H24: =КОММЕРЦИЯ!H8 -> 0 | I24: =КОММЕРЦИЯ!I8 -> 0 | J24: =КОММЕРЦИЯ!J8 -> 0 | K24: =КОММЕРЦИЯ!K8 -> 0 | L24: =КОММЕРЦИЯ!L8 -> 0 | M24: =КОММЕРЦИЯ!M8 -> 0 | N24: =КОММЕРЦИЯ!N8 -> 0 | O24: =КОММЕРЦИЯ!O8 -> 0 | Q24: =КОММЕРЦИЯ!Q8 -> 0 | R24: =КОММЕРЦИЯ!R8 -> 0 | S24: =КОММЕРЦИЯ!S8 -> 0 | T24: =КОММЕРЦИЯ!T8 -> 0 | U24: =КОММЕРЦИЯ!U8 -> 0 | V24: =КОММЕРЦИЯ!V8 -> 0 | W24: =КОММЕРЦИЯ!W8 -> 0 | X24: =КОММЕРЦИЯ!X8 -> 0 | ... AZ24: =КОММЕРЦИЯ!AZ8 -> 0 | BB24: =КОММЕРЦИЯ!BB8 -> 0 | BC24: =КОММЕРЦИЯ!BC8 -> 0 | BD24: =КОММЕРЦИЯ!BD8 -> 0 | BE24: =КОММЕРЦИЯ!BE8 -> 0 | BF24: =КОММЕРЦИЯ!BF8 -> 0 | BG24: =КОММЕРЦИЯ!BG8 -> 0 | BH24: =КОММЕРЦИЯ!BH8 -> 0 | BI24: =КОММЕРЦИЯ!BI8 -> 0 | ... FE24: =КОММЕРЦИЯ!FE8 -> 0
B25: объем законтрактованных площадей, м2 | C25: =КОММЕРЦИЯ!E9 -> 0 | D25: =КОММЕРЦИЯ!E16 -> 0 | E25: =КОММЕРЦИЯ!E23 -> 0 | G25: =КОММЕРЦИЯ!G9 -> 0 | H25: =КОММЕРЦИЯ!H9 -> 0 | I25: =КОММЕРЦИЯ!I9 -> 0 | J25: =КОММЕРЦИЯ!J9 -> 0 | K25: =КОММЕРЦИЯ!K9 -> 0 | L25: =КОММЕРЦИЯ!L9 -> 0 | M25: =КОММЕРЦИЯ!M9 -> 0 | N25: =КОММЕРЦИЯ!N9 -> 0 | O25: =КОММЕРЦИЯ!O9 -> 0 | Q25: =КОММЕРЦИЯ!Q9 -> 0 | R25: =КОММЕРЦИЯ!R9 -> 0 | S25: =КОММЕРЦИЯ!S9 -> 0 | T25: =КОММЕРЦИЯ!T9 -> 0 | U25: =КОММЕРЦИЯ!U9 -> 0 | V25: =КОММЕРЦИЯ!V9 -> 0 | W25: =КОММЕРЦИЯ!W9 -> 0 | X25: =КОММЕРЦИЯ!X9 -> 0 | ... AZ25: =КОММЕРЦИЯ!AZ9 -> 0 | BB25: =КОММЕРЦИЯ!BB9 -> 0 | BC25: =КОММЕРЦИЯ!BC9 -> 0 | BD25: =КОММЕРЦИЯ!BD9 -> 0 | BE25: =КОММЕРЦИЯ!BE9 -> 0 | BF25: =КОММЕРЦИЯ!BF9 -> 0 | BG25: =КОММЕРЦИЯ!BG9 -> 0 | BH25: =КОММЕРЦИЯ!BH9 -> 0 | BI25: =КОММЕРЦИЯ!BI9 -> 0 | ... FE25: =КОММЕРЦИЯ!FE9 -> 0
B26: цена за 1 м2, руб. | C26: =КОММЕРЦИЯ!E10 -> 0 | D26: =КОММЕРЦИЯ!E17 -> 0 | E26: =КОММЕРЦИЯ!E24 -> 0 | G26: =КОММЕРЦИЯ!G10 -> 0 | H26: =КОММЕРЦИЯ!H10 -> 0 | I26: =КОММЕРЦИЯ!I10 -> 0 | J26: =КОММЕРЦИЯ!J10 -> 0 | K26: =КОММЕРЦИЯ!K10 -> 0 | L26: =КОММЕРЦИЯ!L10 -> 0 | M26: =КОММЕРЦИЯ!M10 -> 0 | N26: =КОММЕРЦИЯ!N10 -> 0 | O26: =КОММЕРЦИЯ!O10 -> 0 | Q26: =КОММЕРЦИЯ!Q10 -> 0 | R26: =КОММЕРЦИЯ!R10 -> 0 | S26: =КОММЕРЦИЯ!S10 -> 0 | T26: =КОММЕРЦИЯ!T10 -> 0 | U26: =КОММЕРЦИЯ!U10 -> 0 | V26: =КОММЕРЦИЯ!V10 -> 0 | W26: =КОММЕРЦИЯ!W10 -> 0 | X26: =КОММЕРЦИЯ!X10 -> 0 | ... AZ26: =КОММЕРЦИЯ!AZ10 -> 0 | BB26: =КОММЕРЦИЯ!BB10 -> 0 | BC26: =КОММЕРЦИЯ!BC10 -> 0 | BD26: =КОММЕРЦИЯ!BD10 -> 0 | BE26: =КОММЕРЦИЯ!BE10 -> 0 | BF26: =КОММЕРЦИЯ!BF10 -> 0 | BG26: =КОММЕРЦИЯ!BG10 -> 0 | BH26: =КОММЕРЦИЯ!BH10 -> 0 | BI26: =КОММЕРЦИЯ!BI10 -> 0 | ... FE26: =КОММЕРЦИЯ!FE10 -> 0
B27: объем законтрактованных площадей, шт | C27: =КОММЕРЦИЯ!E11 -> 0 | D27: =КОММЕРЦИЯ!E18 -> 0 | E27: =КОММЕРЦИЯ!E25 -> 0 | G27: =КОММЕРЦИЯ!G11 -> 0 | H27: =КОММЕРЦИЯ!H11 -> 0 | I27: =КОММЕРЦИЯ!I11 -> 0 | J27: =КОММЕРЦИЯ!J11 -> 0 | K27: =КОММЕРЦИЯ!K11 -> 0 | L27: =КОММЕРЦИЯ!L11 -> 0 | M27: =КОММЕРЦИЯ!M11 -> 0 | N27: =КОММЕРЦИЯ!N11 -> 0 | O27: =КОММЕРЦИЯ!O11 -> 0 | Q27: =КОММЕРЦИЯ!Q11 -> 0 | R27: =КОММЕРЦИЯ!R11 -> 0 | S27: =КОММЕРЦИЯ!S11 -> 0 | T27: =КОММЕРЦИЯ!T11 -> 0 | U27: =КОММЕРЦИЯ!U11 -> 0 | V27: =КОММЕРЦИЯ!V11 -> 0 | W27: =КОММЕРЦИЯ!W11 -> 0 | X27: =КОММЕРЦИЯ!X11 -> 0 | ... AZ27: =КОММЕРЦИЯ!AZ11 -> 0 | BB27: =КОММЕРЦИЯ!BB11 -> 0 | BC27: =КОММЕРЦИЯ!BC11 -> 0 | BD27: =КОММЕРЦИЯ!BD11 -> 0 | BE27: =КОММЕРЦИЯ!BE11 -> 0 | BF27: =КОММЕРЦИЯ!BF11 -> 0 | BG27: =КОММЕРЦИЯ!BG11 -> 0 | BH27: =КОММЕРЦИЯ!BH11 -> 0 | BI27: =КОММЕРЦИЯ!BI11 -> 0 | ... FE27: =КОММЕРЦИЯ!FE11 -> 0
B28: Поступление ден. средств, руб. | C28: =КОММЕРЦИЯ!E12 -> 0 | D28: =КОММЕРЦИЯ!E19 -> 0 | E28: =КОММЕРЦИЯ!E26 -> 0 | G28: =КОММЕРЦИЯ!G12 -> 0 | H28: =КОММЕРЦИЯ!H12 -> 0 | I28: =КОММЕРЦИЯ!I12 -> 0 | J28: =КОММЕРЦИЯ!J12 -> 0 | K28: =КОММЕРЦИЯ!K12 -> 0 | L28: =КОММЕРЦИЯ!L12 -> 0 | M28: =КОММЕРЦИЯ!M12 -> 0 | N28: =КОММЕРЦИЯ!N12 -> 0 | O28: =КОММЕРЦИЯ!O12 -> 0 | Q28: =КОММЕРЦИЯ!Q12 -> 0 | R28: =КОММЕРЦИЯ!R12 -> 0 | S28: =КОММЕРЦИЯ!S12 -> 0 | T28: =КОММЕРЦИЯ!T12 -> 0 | U28: =КОММЕРЦИЯ!U12 -> 0 | V28: =КОММЕРЦИЯ!V12 -> 0 | W28: =КОММЕРЦИЯ!W12 -> 0 | X28: =КОММЕРЦИЯ!X12 -> 0 | ... AZ28: =КОММЕРЦИЯ!AZ12 -> 0 | BB28: =КОММЕРЦИЯ!BB12 -> 0 | BC28: =КОММЕРЦИЯ!BC12 -> 0 | BD28: =КОММЕРЦИЯ!BD12 -> 0 | BE28: =КОММЕРЦИЯ!BE12 -> 0 | BF28: =КОММЕРЦИЯ!BF12 -> 0 | BG28: =КОММЕРЦИЯ!BG12 -> 0 | BH28: =КОММЕРЦИЯ!BH12 -> 0 | BI28: =КОММЕРЦИЯ!BI12 -> 0 | ... FE28: =КОММЕРЦИЯ!FE12 -> 0
B30: КЛАДОВКИ | C30: ИТОГО | D30: ПРОДАНО | E30: ОСТАТОК К ПРОДАЖЕ | G30: 2025 | H30: 2026 | I30: 2027 | J30: 2028 | K30: 2029 | L30: 2030 | M30: 2031 | N30: 2032 | O30: 2033 | Q30: 1 кв. 2025 | R30: 2 кв. 2025 | S30: 3 кв. 2025 | T30: 4 кв. 2025 | U30: 1 кв. 2026 | V30: 2 кв. 2026 | W30: 3 кв. 2026 | X30: 4 кв. 2026 | Y30: 1 кв. 2027 | Z30: 2 кв. 2027 | AA30: 3 кв. 2027 | AB30: 4 кв. 2027 | AC30: 1 кв. 2028 | AD30: 2 кв. 2028 | AE30: 3 кв. 2028 | AF30: 4 кв. 2028 | AG30: 1 кв. 2029 | AH30: 2 кв. 2029 | AI30: 3 кв. 2029 | AJ30: 4 кв. 2029 | AK30: 1 кв. 2030 | AL30: 2 кв. 2030 | AM30: 3 кв. 2030 | AN30: 4 кв. 2030 | AO30: 1 кв. 2031 | AP30: 2 кв. 2031 | AQ30: 3 кв. 2031 | AR30: 4 кв. 2031 | AS30: 1 кв. 2032 | AT30: 2 кв. 2032 | AU30: 3 кв. 2032 | AV30: 4 кв. 2032 | AW30: 1 кв. 2033 | AX30: 2 кв. 2033 | AY30: 3 кв. 2033 | AZ30: 4 кв. 2033 | BB30: 45658 | BC30: 45689 | BD30: 45717 | BE30: 45748 | BF30: 45778 | BG30: 45809 | BH30: 45839 | BI30: 45870 | BJ30: 45901 | BK30: 45931 | BL30: 45962 | BM30: 45992 | BN30: 46023 | BO30: 46054 | BP30: 46082 | BQ30: 46113 | BR30: 46143 | BS30: 46174 | BT30: 46204 | BU30: 46235 | BV30: 46266 | BW30: 46296 | BX30: 46327 | BY30: 46357 | BZ30: 46388 | CA30: 46419 | CB30: 46447 | CC30: 46478 | CD30: 46508 | CE30: 46539 | CF30: 46569 | CG30: 46600 | CH30: 46631 | CI30: 46661 | CJ30: 46692 | CK30: 46722 | CL30: 46753 | CM30: 46784 | CN30: 46813 | CO30: 46844 | CP30: 46874 | CQ30: 46905 | CR30: 46935 | CS30: 46966 | CT30: 46997 | CU30: 47027 | CV30: 47058 | CW30: 47088 | CX30: 47119 | CY30: 47150 | CZ30: 47178 | DA30: 47209 | DB30: 47239 | DC30: 47270 | DD30: 47300 | DE30: 47331 | DF30: 47362 | DG30: 47392 | DH30: 47423 | DI30: 47453 | DJ30: 47484 | DK30: 47515 | DL30: 47543 | DM30: 47574 | DN30: 47604 | DO30: 47635 | DP30: 47665 | DQ30: 47696 | DR30: 47727 | DS30: 47757 | DT30: 47788 | DU30: 47818 | DV30: 47849 | DW30: 47880 | DX30: 47908 | DY30: 47939 | DZ30: 47969 | EA30: 48000 | EB30: 48030 | EC30: 48061 | ED30: 48092 | EE30: 48122 | EF30: 48153 | EG30: 48183 | EH30: 48214 | EI30: 48245 | EJ30: 48274 | EK30: 48305 | EL30: 48335 | EM30: 48366 | EN30: 48396 | EO30: 48427 | EP30: 48458 | EQ30: 48488 | ER30: 48519 | ES30: 48549 | ET30: 48580 | EU30: 48611 | EV30: 48639 | EW30: 48670 | EX30: 48700 | EY30: 48731 | EZ30: 48761 | FA30: 48792 | FB30: 48823 | FC30: 48853 | FD30: 48884 | FE30: 48914
B31: Продажи, руб. | C31: =КЛАДОВКИ!E8 -> 0 | D31: =КЛАДОВКИ!E15 -> 0 | E31: =КЛАДОВКИ!E22 -> 0 | G31: =КЛАДОВКИ!G8 -> 0 | H31: =КЛАДОВКИ!H8 -> 0 | I31: =КЛАДОВКИ!I8 -> 0 | J31: =КЛАДОВКИ!J8 -> 0 | K31: =КЛАДОВКИ!K8 -> 0 | L31: =КЛАДОВКИ!L8 -> 0 | M31: =КЛАДОВКИ!M8 -> 0 | N31: =КЛАДОВКИ!N8 -> 0 | O31: =КЛАДОВКИ!O8 -> 0 | Q31: =КЛАДОВКИ!Q8 -> 0 | R31: =КЛАДОВКИ!R8 -> 0 | S31: =КЛАДОВКИ!S8 -> 0 | T31: =КЛАДОВКИ!T8 -> 0 | U31: =КЛАДОВКИ!U8 -> 0 | V31: =КЛАДОВКИ!V8 -> 0 | W31: =КЛАДОВКИ!W8 -> 0 | X31: =КЛАДОВКИ!X8 -> 0 | ... AZ31: =КЛАДОВКИ!AZ8 -> 0 | BB31: =КЛАДОВКИ!BB8 -> 0 | BC31: =КЛАДОВКИ!BC8 -> 0 | BD31: =КЛАДОВКИ!BD8 -> 0 | BE31: =КЛАДОВКИ!BE8 -> 0 | BF31: =КЛАДОВКИ!BF8 -> 0 | BG31: =КЛАДОВКИ!BG8 -> 0 | BH31: =КЛАДОВКИ!BH8 -> 0 | BI31: =КЛАДОВКИ!BI8 -> 0 | ... FE31: =КЛАДОВКИ!FE8 -> 0
B32: объем законтрактованных площадей, м2 | C32: =КЛАДОВКИ!E9 -> 0 | D32: =КЛАДОВКИ!E16 -> 0 | E32: =КЛАДОВКИ!E23 -> 0 | G32: =КЛАДОВКИ!G9 -> 0 | H32: =КЛАДОВКИ!H9 -> 0 | I32: =КЛАДОВКИ!I9 -> 0 | J32: =КЛАДОВКИ!J9 -> 0 | K32: =КЛАДОВКИ!K9 -> 0 | L32: =КЛАДОВКИ!L9 -> 0 | M32: =КЛАДОВКИ!M9 -> 0 | N32: =КЛАДОВКИ!N9 -> 0 | O32: =КЛАДОВКИ!O9 -> 0 | Q32: =КЛАДОВКИ!Q9 -> 0 | R32: =КЛАДОВКИ!R9 -> 0 | S32: =КЛАДОВКИ!S9 -> 0 | T32: =КЛАДОВКИ!T9 -> 0 | U32: =КЛАДОВКИ!U9 -> 0 | V32: =КЛАДОВКИ!V9 -> 0 | W32: =КЛАДОВКИ!W9 -> 0 | X32: =КЛАДОВКИ!X9 -> 0 | ... AZ32: =КЛАДОВКИ!AZ9 -> 0 | BB32: =КЛАДОВКИ!BB9 -> 0 | BC32: =КЛАДОВКИ!BC9 -> 0 | BD32: =КЛАДОВКИ!BD9 -> 0 | BE32: =КЛАДОВКИ!BE9 -> 0 | BF32: =КЛАДОВКИ!BF9 -> 0 | BG32: =КЛАДОВКИ!BG9 -> 0 | BH32: =КЛАДОВКИ!BH9 -> 0 | BI32: =КЛАДОВКИ!BI9 -> 0 | ... FE32: =КЛАДОВКИ!FE9 -> 0
B33: цена за 1 м2, руб. | C33: =КЛАДОВКИ!E10 -> 0 | D33: =КЛАДОВКИ!E17 -> 0 | E33: =КЛАДОВКИ!E24 -> 0 | G33: =КЛАДОВКИ!G10 -> 0 | H33: =КЛАДОВКИ!H10 -> 0 | I33: =КЛАДОВКИ!I10 -> 0 | J33: =КЛАДОВКИ!J10 -> 0 | K33: =КЛАДОВКИ!K10 -> 0 | L33: =КЛАДОВКИ!L10 -> 0 | M33: =КЛАДОВКИ!M10 -> 0 | N33: =КЛАДОВКИ!N10 -> 0 | O33: =КЛАДОВКИ!O10 -> 0 | Q33: =КЛАДОВКИ!Q10 -> 0 | R33: =КЛАДОВКИ!R10 -> 0 | S33: =КЛАДОВКИ!S10 -> 0 | T33: =КЛАДОВКИ!T10 -> 0 | U33: =КЛАДОВКИ!U10 -> 0 | V33: =КЛАДОВКИ!V10 -> 0 | W33: =КЛАДОВКИ!W10 -> 0 | X33: =КЛАДОВКИ!X10 -> 0 | ... AZ33: =КЛАДОВКИ!AZ10 -> 0 | BB33: =КЛАДОВКИ!BB10 -> 0 | BC33: =КЛАДОВКИ!BC10 -> 0 | BD33: =КЛАДОВКИ!BD10 -> 0 | BE33: =КЛАДОВКИ!BE10 -> 0 | BF33: =КЛАДОВКИ!BF10 -> 0 | BG33: =КЛАДОВКИ!BG10 -> 0 | BH33: =КЛАДОВКИ!BH10 -> 0 | BI33: =КЛАДОВКИ!BI10 -> 0 | ... FE33: =КЛАДОВКИ!FE10 -> 0
B34: объем законтрактованных площадей, шт | C34: =КЛАДОВКИ!E11 -> 0 | D34: =КЛАДОВКИ!E18 -> 0 | E34: =КЛАДОВКИ!E25 -> 0 | G34: =КЛАДОВКИ!G11 -> 0 | H34: =КЛАДОВКИ!H11 -> 0 | I34: =КЛАДОВКИ!I11 -> 0 | J34: =КЛАДОВКИ!J11 -> 0 | K34: =КЛАДОВКИ!K11 -> 0 | L34: =КЛАДОВКИ!L11 -> 0 | M34: =КЛАДОВКИ!M11 -> 0 | N34: =КЛАДОВКИ!N11 -> 0 | O34: =КЛАДОВКИ!O11 -> 0 | Q34: =КЛАДОВКИ!Q11 -> 0 | R34: =КЛАДОВКИ!R11 -> 0 | S34: =КЛАДОВКИ!S11 -> 0 | T34: =КЛАДОВКИ!T11 -> 0 | U34: =КЛАДОВКИ!U11 -> 0 | V34: =КЛАДОВКИ!V11 -> 0 | W34: =КЛАДОВКИ!W11 -> 0 | X34: =КЛАДОВКИ!X11 -> 0 | ... AZ34: =КЛАДОВКИ!AZ11 -> 0 | BB34: =КЛАДОВКИ!BB11 -> 0 | BC34: =КЛАДОВКИ!BC11 -> 0 | BD34: =КЛАДОВКИ!BD11 -> 0 | BE34: =КЛАДОВКИ!BE11 -> 0 | BF34: =КЛАДОВКИ!BF11 -> 0 | BG34: =КЛАДОВКИ!BG11 -> 0 | BH34: =КЛАДОВКИ!BH11 -> 0 | BI34: =КЛАДОВКИ!BI11 -> 0 | ... FE34: =КЛАДОВКИ!FE11 -> 0
B35: Поступление ден. средств, руб. | C35: =КЛАДОВКИ!E12 -> 0 | D35: =КЛАДОВКИ!E19 -> 0 | E35: =КЛАДОВКИ!E26 -> 0 | G35: =КЛАДОВКИ!G12 -> 0 | H35: =КЛАДОВКИ!H12 -> 0 | I35: =КЛАДОВКИ!I12 -> 0 | J35: =КЛАДОВКИ!J12 -> 0 | K35: =КЛАДОВКИ!K12 -> 0 | L35: =КЛАДОВКИ!L12 -> 0 | M35: =КЛАДОВКИ!M12 -> 0 | N35: =КЛАДОВКИ!N12 -> 0 | O35: =КЛАДОВКИ!O12 -> 0 | Q35: =КЛАДОВКИ!Q12 -> 0 | R35: =КЛАДОВКИ!R12 -> 0 | S35: =КЛАДОВКИ!S12 -> 0 | T35: =КЛАДОВКИ!T12 -> 0 | U35: =КЛАДОВКИ!U12 -> 0 | V35: =КЛАДОВКИ!V12 -> 0 | W35: =КЛАДОВКИ!W12 -> 0 | X35: =КЛАДОВКИ!X12 -> 0 | ... AZ35: =КЛАДОВКИ!AZ12 -> 0 | BB35: =КЛАДОВКИ!BB12 -> 0 | BC35: =КЛАДОВКИ!BC12 -> 0 | BD35: =КЛАДОВКИ!BD12 -> 0 | BE35: =КЛАДОВКИ!BE12 -> 0 | BF35: =КЛАДОВКИ!BF12 -> 0 | BG35: =КЛАДОВКИ!BG12 -> 0 | BH35: =КЛАДОВКИ!BH12 -> 0 | BI35: =КЛАДОВКИ!BI12 -> 0 | ... FE35: =КЛАДОВКИ!FE12 -> 0
B37: МАШИНОМЕСТА | C37: ИТОГО | D37: ПРОДАНО | E37: ОСТАТОК К ПРОДАЖЕ | G37: 2025 | H37: 2026 | I37: 2027 | J37: 2028 | K37: 2029 | L37: 2030 | M37: 2031 | N37: 2032 | O37: 2033 | Q37: 1 кв. 2025 | R37: 2 кв. 2025 | S37: 3 кв. 2025 | T37: 4 кв. 2025 | U37: 1 кв. 2026 | V37: 2 кв. 2026 | W37: 3 кв. 2026 | X37: 4 кв. 2026 | Y37: 1 кв. 2027 | Z37: 2 кв. 2027 | AA37: 3 кв. 2027 | AB37: 4 кв. 2027 | AC37: 1 кв. 2028 | AD37: 2 кв. 2028 | AE37: 3 кв. 2028 | AF37: 4 кв. 2028 | AG37: 1 кв. 2029 | AH37: 2 кв. 2029 | AI37: 3 кв. 2029 | AJ37: 4 кв. 2029 | AK37: 1 кв. 2030 | AL37: 2 кв. 2030 | AM37: 3 кв. 2030 | AN37: 4 кв. 2030 | AO37: 1 кв. 2031 | AP37: 2 кв. 2031 | AQ37: 3 кв. 2031 | AR37: 4 кв. 2031 | AS37: 1 кв. 2032 | AT37: 2 кв. 2032 | AU37: 3 кв. 2032 | AV37: 4 кв. 2032 | AW37: 1 кв. 2033 | AX37: 2 кв. 2033 | AY37: 3 кв. 2033 | AZ37: 4 кв. 2033 | BB37: 45658 | BC37: 45689 | BD37: 45717 | BE37: 45748 | BF37: 45778 | BG37: 45809 | BH37: 45839 | BI37: 45870 | BJ37: 45901 | BK37: 45931 | BL37: 45962 | BM37: 45992 | BN37: 46023 | BO37: 46054 | BP37: 46082 | BQ37: 46113 | BR37: 46143 | BS37: 46174 | BT37: 46204 | BU37: 46235 | BV37: 46266 | BW37: 46296 | BX37: 46327 | BY37: 46357 | BZ37: 46388 | CA37: 46419 | CB37: 46447 | CC37: 46478 | CD37: 46508 | CE37: 46539 | CF37: 46569 | CG37: 46600 | CH37: 46631 | CI37: 46661 | CJ37: 46692 | CK37: 46722 | CL37: 46753 | CM37: 46784 | CN37: 46813 | CO37: 46844 | CP37: 46874 | CQ37: 46905 | CR37: 46935 | CS37: 46966 | CT37: 46997 | CU37: 47027 | CV37: 47058 | CW37: 47088 | CX37: 47119 | CY37: 47150 | CZ37: 47178 | DA37: 47209 | DB37: 47239 | DC37: 47270 | DD37: 47300 | DE37: 47331 | DF37: 47362 | DG37: 47392 | DH37: 47423 | DI37: 47453 | DJ37: 47484 | DK37: 47515 | DL37: 47543 | DM37: 47574 | DN37: 47604 | DO37: 47635 | DP37: 47665 | DQ37: 47696 | DR37: 47727 | DS37: 47757 | DT37: 47788 | DU37: 47818 | DV37: 47849 | DW37: 47880 | DX37: 47908 | DY37: 47939 | DZ37: 47969 | EA37: 48000 | EB37: 48030 | EC37: 48061 | ED37: 48092 | EE37: 48122 | EF37: 48153 | EG37: 48183 | EH37: 48214 | EI37: 48245 | EJ37: 48274 | EK37: 48305 | EL37: 48335 | EM37: 48366 | EN37: 48396 | EO37: 48427 | EP37: 48458 | EQ37: 48488 | ER37: 48519 | ES37: 48549 | ET37: 48580 | EU37: 48611 | EV37: 48639 | EW37: 48670 | EX37: 48700 | EY37: 48731 | EZ37: 48761 | FA37: 48792 | FB37: 48823 | FC37: 48853 | FD37: 48884 | FE37: 48914
B38: Продажи, руб. | C38: =МАШИНОМЕСТА!E8 -> 0 | D38: =МАШИНОМЕСТА!E14 -> 0 | E38: =МАШИНОМЕСТА!E20 -> 0 | G38: =МАШИНОМЕСТА!G8 -> 0 | H38: =МАШИНОМЕСТА!H8 -> 0 | I38: =МАШИНОМЕСТА!I8 -> 0 | J38: =МАШИНОМЕСТА!J8 -> 0 | K38: =МАШИНОМЕСТА!K8 -> 0 | L38: =МАШИНОМЕСТА!L8 -> 0 | M38: =МАШИНОМЕСТА!M8 -> 0 | N38: =МАШИНОМЕСТА!N8 -> 0 | O38: =МАШИНОМЕСТА!O8 -> 0 | Q38: =МАШИНОМЕСТА!Q8 -> 0 | R38: =МАШИНОМЕСТА!R8 -> 0 | S38: =МАШИНОМЕСТА!S8 -> 0 | T38: =МАШИНОМЕСТА!T8 -> 0 | U38: =МАШИНОМЕСТА!U8 -> 0 | V38: =МАШИНОМЕСТА!V8 -> 0 | W38: =МАШИНОМЕСТА!W8 -> 0 | X38: =МАШИНОМЕСТА!X8 -> 0 | ... AZ38: =МАШИНОМЕСТА!AZ8 -> 0 | BB38: =МАШИНОМЕСТА!BB8 -> 0 | BC38: =МАШИНОМЕСТА!BC8 -> 0 | BD38: =МАШИНОМЕСТА!BD8 -> 0 | BE38: =МАШИНОМЕСТА!BE8 -> 0 | BF38: =МАШИНОМЕСТА!BF8 -> 0 | BG38: =МАШИНОМЕСТА!BG8 -> 0 | BH38: =МАШИНОМЕСТА!BH8 -> 0 | BI38: =МАШИНОМЕСТА!BI8 -> 0 | ... FE38: =МАШИНОМЕСТА!FE8 -> 0
B39: объем законтрактованных м-мест, шт | C39: =МАШИНОМЕСТА!E9 -> 0 | D39: =МАШИНОМЕСТА!E15 -> 0 | E39: =МАШИНОМЕСТА!E21 -> 0 | G39: =МАШИНОМЕСТА!G9 -> 0 | H39: =МАШИНОМЕСТА!H9 -> 0 | I39: =МАШИНОМЕСТА!I9 -> 0 | J39: =МАШИНОМЕСТА!J9 -> 0 | K39: =МАШИНОМЕСТА!K9 -> 0 | L39: =МАШИНОМЕСТА!L9 -> 0 | M39: =МАШИНОМЕСТА!M9 -> 0 | N39: =МАШИНОМЕСТА!N9 -> 0 | O39: =МАШИНОМЕСТА!O9 -> 0 | Q39: =МАШИНОМЕСТА!Q9 -> 0 | R39: =МАШИНОМЕСТА!R9 -> 0 | S39: =МАШИНОМЕСТА!S9 -> 0 | T39: =МАШИНОМЕСТА!T9 -> 0 | U39: =МАШИНОМЕСТА!U9 -> 0 | V39: =МАШИНОМЕСТА!V9 -> 0 | W39: =МАШИНОМЕСТА!W9 -> 0 | X39: =МАШИНОМЕСТА!X9 -> 0 | ... AZ39: =МАШИНОМЕСТА!AZ9 -> 0 | BB39: =МАШИНОМЕСТА!BB9 -> 0 | BC39: =МАШИНОМЕСТА!BC9 -> 0 | BD39: =МАШИНОМЕСТА!BD9 -> 0 | BE39: =МАШИНОМЕСТА!BE9 -> 0 | BF39: =МАШИНОМЕСТА!BF9 -> 0 | BG39: =МАШИНОМЕСТА!BG9 -> 0 | BH39: =МАШИНОМЕСТА!BH9 -> 0 | BI39: =МАШИНОМЕСТА!BI9 -> 0 | ... FE39: =МАШИНОМЕСТА!FE9 -> 0
B40: цена за 1 место, руб. | C40: =МАШИНОМЕСТА!E10 -> 0 | D40: =МАШИНОМЕСТА!E16 -> 0 | E40: =МАШИНОМЕСТА!E22 -> 0 | G40: =МАШИНОМЕСТА!G10 -> 0 | H40: =МАШИНОМЕСТА!H10 -> 0 | I40: =МАШИНОМЕСТА!I10 -> 0 | J40: =МАШИНОМЕСТА!J10 -> 0 | K40: =МАШИНОМЕСТА!K10 -> 0 | L40: =МАШИНОМЕСТА!L10 -> 0 | M40: =МАШИНОМЕСТА!M10 -> 0 | N40: =МАШИНОМЕСТА!N10 -> 0 | O40: =МАШИНОМЕСТА!O10 -> 0 | Q40: =МАШИНОМЕСТА!Q10 -> 0 | R40: =МАШИНОМЕСТА!R10 -> 0 | S40: =МАШИНОМЕСТА!S10 -> 0 | T40: =МАШИНОМЕСТА!T10 -> 0 | U40: =МАШИНОМЕСТА!U10 -> 0 | V40: =МАШИНОМЕСТА!V10 -> 0 | W40: =МАШИНОМЕСТА!W10 -> 0 | X40: =МАШИНОМЕСТА!X10 -> 0 | ... AZ40: =МАШИНОМЕСТА!AZ10 -> 0 | BB40: =МАШИНОМЕСТА!BB10 -> 0 | BC40: =МАШИНОМЕСТА!BC10 -> 0 | BD40: =МАШИНОМЕСТА!BD10 -> 0 | BE40: =МАШИНОМЕСТА!BE10 -> 0 | BF40: =МАШИНОМЕСТА!BF10 -> 0 | BG40: =МАШИНОМЕСТА!BG10 -> 0 | BH40: =МАШИНОМЕСТА!BH10 -> 0 | BI40: =МАШИНОМЕСТА!BI10 -> 0 | ... FE40: =МАШИНОМЕСТА!FE10 -> 0
B41: Поступление ден. средств, руб. | C41: =МАШИНОМЕСТА!E11 -> 0 | D41: =МАШИНОМЕСТА!E17 -> 0 | E41: =МАШИНОМЕСТА!E23 -> 0 | G41: =МАШИНОМЕСТА!G11 -> 0 | H41: =МАШИНОМЕСТА!H11 -> 0 | I41: =МАШИНОМЕСТА!I11 -> 0 | J41: =МАШИНОМЕСТА!J11 -> 0 | K41: =МАШИНОМЕСТА!K11 -> 0 | L41: =МАШИНОМЕСТА!L11 -> 0 | M41: =МАШИНОМЕСТА!M11 -> 0 | N41: =МАШИНОМЕСТА!N11 -> 0 | O41: =МАШИНОМЕСТА!O11 -> 0 | Q41: =МАШИНОМЕСТА!Q11 -> 0 | R41: =МАШИНОМЕСТА!R11 -> 0 | S41: =МАШИНОМЕСТА!S11 -> 0 | T41: =МАШИНОМЕСТА!T11 -> 0 | U41: =МАШИНОМЕСТА!U11 -> 0 | V41: =МАШИНОМЕСТА!V11 -> 0 | W41: =МАШИНОМЕСТА!W11 -> 0 | X41: =МАШИНОМЕСТА!X11 -> 0 | ... AZ41: =МАШИНОМЕСТА!AZ11 -> 0 | BB41: =МАШИНОМЕСТА!BB11 -> 0 | BC41: =МАШИНОМЕСТА!BC11 -> 0 | BD41: =МАШИНОМЕСТА!BD11 -> 0 | BE41: =МАШИНОМЕСТА!BE11 -> 0 | BF41: =МАШИНОМЕСТА!BF11 -> 0 | BG41: =МАШИНОМЕСТА!BG11 -> 0 | BH41: =МАШИНОМЕСТА!BH11 -> 0 | BI41: =МАШИНОМЕСТА!BI11 -> 0 | ... FE41: =МАШИНОМЕСТА!FE11 -> 0

Sheet ЖИЛЬЕ
B1: Вспомогательная строка (для суммирования) | Q1: 1 кв | R1: 2 кв | S1: 3 кв | T1: 4 кв | U1: 1 кв | V1: 2 кв | W1: 3 кв | X1: 4 кв | Y1: 1 кв | Z1: 2 кв | AA1: 3 кв | AB1: 4 кв | AC1: 1 кв | AD1: 2 кв | AE1: 3 кв | AF1: 4 кв | AG1: 1 кв | AH1: 2 кв | AI1: 3 кв | AJ1: 4 кв | AK1: 1 кв | AL1: 2 кв | AM1: 3 кв | AN1: 4 кв | AO1: 1 кв | AP1: 2 кв | AQ1: 3 кв | AR1: 4 кв | AS1: 1 кв | AT1: 2 кв | AU1: 3 кв | AV1: 4 кв | AW1: 1 кв | AX1: 2 кв | AY1: 3 кв | AZ1: 4 кв | BB1: 1 кв | BC1: 1 кв | BD1: 1 кв | BE1: 2 кв | BF1: 2 кв | BG1: 2 кв | BH1: 3 кв | BI1: 3 кв | BJ1: 3 кв | BK1: 4 кв | BL1: 4 кв | BM1: 4 кв | BN1: 1 кв | BO1: 1 кв | BP1: 1 кв | BQ1: 2 кв | BR1: 2 кв | BS1: 2 кв | BT1: 3 кв | BU1: 3 кв | BV1: 3 кв | BW1: 4 кв | BX1: 4 кв | BY1: 4 кв | BZ1: 1 кв | CA1: 1 кв | CB1: 1 кв | CC1: 2 кв | CD1: 2 кв | CE1: 2 кв | CF1: 3 кв | CG1: 3 кв | CH1: 3 кв | CI1: 4 кв | CJ1: 4 кв | CK1: 4 кв | CL1: 1 кв | CM1: 1 кв | CN1: 1 кв | CO1: 2 кв | CP1: 2 кв | CQ1: 2 кв | CR1: 3 кв | CS1: 3 кв | CT1: 3 кв | CU1: 4 кв | CV1: 4 кв | CW1: 4 кв | CX1: 1 кв | CY1: 1 кв | CZ1: 1 кв | DA1: 2 кв | DB1: 2 кв | DC1: 2 кв | DD1: 3 кв | DE1: 3 кв | DF1: 3 кв | DG1: 4 кв | DH1: 4 кв | DI1: 4 кв | DJ1: 1 кв | DK1: 1 кв | DL1: 1 кв | DM1: 2 кв | DN1: 2 кв | DO1: 2 кв | DP1: 3 кв | DQ1: 3 кв | DR1: 3 кв | DS1: 4 кв | DT1: 4 кв | DU1: 4 кв | DV1: 1 кв | DW1: 1 кв | DX1: 1 кв | DY1: 2 кв | DZ1: 2 кв | EA1: 2 кв | EB1: 3 кв | EC1: 3 кв | ED1: 3 кв | EE1: 4 кв | EF1: 4 кв | EG1: 4 кв | EH1: 1 кв | EI1: 1 кв | EJ1: 1 кв | EK1: 2 кв | EL1: 2 кв | EM1: 2 кв | EN1: 3 кв | EO1: 3 кв | EP1: 3 кв | EQ1: 4 кв | ER1: 4 кв | ES1: 4 кв | ET1: 1 кв | EU1: 1 кв | EV1: 1 кв | EW1: 2 кв | EX1: 2 кв | EY1: 2 кв | EZ1: 3 кв | FA1: 3 кв | FB1: 3 кв | FC1: 4 кв | FD1: 4 кв | FE1: 4 кв
B2: Вспомогательная строка (для суммирования) | Q2: 2025 | R2: 2025 | S2: 2025 | T2: 2025 | U2: 2026 | V2: 2026 | W2: 2026 | X2: 2026 | Y2: 2027 | Z2: 2027 | AA2: 2027 | AB2: 2027 | AC2: 2028 | AD2: 2028 | AE2: 2028 | AF2: 2028 | AG2: 2029 | AH2: 2029 | AI2: 2029 | AJ2: 2029 | AK2: 2030 | AL2: 2030 | AM2: 2030 | AN2: 2030 | AO2: 2031 | AP2: 2031 | AQ2: 2031 | AR2: 2031 | AS2: 2032 | AT2: 2032 | AU2: 2032 | AV2: 2032 | AW2: 2033 | AX2: 2033 | AY2: 2033 | AZ2: 2033 | BB2: =YEAR(BB6) -> 2025 | BC2: =YEAR(BC6) -> 2025 | BD2: =YEAR(BD6) -> 2025 | BE2: =YEAR(BE6) -> 2025 | BF2: =YEAR(BF6) -> 2025 | BG2: =YEAR(BG6) -> 2025 | BH2: =YEAR(BH6) -> 2025 | BI2: =YEAR(BI6) -> 2025 | ... FE2: =YEAR(FE6) -> 2033
B6: ЖИЛЬЕ | C6: ИТОГО по проекту | D6: проверка | E6: ИТОГО | G6: 2025 | H6: 2026 | I6: 2027 | J6: 2028 | K6: 2029 | L6: 2030 | M6: 2031 | N6: 2032 | O6: 2033 | Q6: 1 кв. 2025 | R6: 2 кв. 2025 | S6: 3 кв. 2025 | T6: 4 кв. 2025 | U6: 1 кв. 2026 | V6: 2 кв. 2026 | W6: 3 кв. 2026 | X6: 4 кв. 2026 | Y6: 1 кв. 2027 | Z6: 2 кв. 2027 | AA6: 3 кв. 2027 | AB6: 4 кв. 2027 | AC6: 1 кв. 2028 | AD6: 2 кв. 2028 | AE6: 3 кв. 2028 | AF6: 4 кв. 2028 | AG6: 1 кв. 2029 | AH6: 2 кв. 2029 | AI6: 3 кв. 2029 | AJ6: 4 кв. 2029 | AK6: 1 кв. 2030 | AL6: 2 кв. 2030 | AM6: 3 кв. 2030 | AN6: 4 кв. 2030 | AO6: 1 кв. 2031 | AP6: 2 кв. 2031 | AQ6: 3 кв. 2031 | AR6: 4 кв. 2031 | AS6: 1 кв. 2032 | AT6: 2 кв. 2032 | AU6: 3 кв. 2032 | AV6: 4 кв. 2032 | AW6: 1 кв. 2033 | AX6: 2 кв. 2033 | AY6: 3 кв. 2033 | AZ6: 4 кв. 2033 | BB6: 45658 | BC6: 45689 | BD6: 45717 | BE6: 45748 | BF6: 45778 | BG6: 45809 | BH6: 45839 | BI6: 45870 | BJ6: 45901 | BK6: 45931 | BL6: 45962 | BM6: 45992 | BN6: 46023 | BO6: 46054 | BP6: 46082 | BQ6: 46113 | BR6: 46143 | BS6: 46174 | BT6: 46204 | BU6: 46235 | BV6: 46266 | BW6: 46296 | BX6: 46327 | BY6: 46357 | BZ6: 46388 | CA6: 46419 | CB6: 46447 | CC6: 46478 | CD6: 46508 | CE6: 46539 | CF6: 46569 | CG6: 46600 | CH6: 46631 | CI6: 46661 | CJ6: 46692 | CK6: 46722 | CL6: 46753 | CM6: 46784 | CN6: 46813 | CO6: 46844 | CP6: 46874 | CQ6: 46905 | CR6: 46935 | CS6: 46966 | CT6: 46997 | CU6: 47027 | CV6: 47058 | CW6: 47088 | CX6: 47119 | CY6: 47150 | CZ6: 47178 | DA6: 47209 | DB6: 47239 | DC6: 47270 | DD6: 47300 | DE6: 47331 | DF6: 47362 | DG6: 47392 | DH6: 47423 | DI6: 47453 | DJ6: 47484 | DK6: 47515 | DL6: 47543 | DM6: 47574 | DN6: 47604 | DO6: 47635 | DP6: 47665 | DQ6: 47696 | DR6: 47727 | DS6: 47757 | DT6: 47788 | DU6: 47818 | DV6: 47849 | DW6: 47880 | DX6: 47908 | DY6: 47939 | DZ6: 47969 | EA6: 48000 | EB6: 48030 | EC6: 48061 | ED6: 48092 | EE6: 48122 | EF6: 48153 | EG6: 48183 | EH6: 48214 | EI6: 48245 | EJ6: 48274 | EK6: 48305 | EL6: 48335 | EM6: 48366 | EN6: 48396 | EO6: 48427 | EP6: 48458 | EQ6: 48488 | ER6: 48519 | ES6: 48549 | ET6: 48580 | EU6: 48611 | EV6: 48639 | EW6: 48670 | EX6: 48700 | EY6: 48731 | EZ6: 48761 | FA6: 48792 | FB6: 48823 | FC6: 48853 | FD6: 48884 | FE6: 48914
B7: ИТОГО ПО ПРОЕКТУ / ОЧЕРЕДИ
B8: Продажи, руб. | D8: =E8=E12 -> TRUE | E8: =SUM(BB8:FE8) -> 0 | G8: =SUMIFS($BB8:$FE8,$BB$2:$FE$2,G$6) -> 0 | H8: =SUMIFS($BB8:$FE8,$BB$2:$FE$2,H$6) -> 0 | I8: =SUMIFS($BB8:$FE8,$BB$2:$FE$2,I$6) -> 0 | J8: =SUMIFS($BB8:$FE8,$BB$2:$FE$2,J$6) -> 0 | K8: =SUMIFS($BB8:$FE8,$BB$2:$FE$2,K$6) -> 0 | L8: =SUMIFS($BB8:$FE8,$BB$2:$FE$2,L$6) -> 0 | M8: =SUMIFS($BB8:$FE8,$BB$2:$FE$2,M$6) -> 0 | N8: =SUMIFS($BB8:$FE8,$BB$2:$FE$2,N$6) -> 0 | O8: =SUMIFS($BB8:$FE8,$BB$2:$FE$2,O$6) -> 0 | Q8: =SUMIFS($BB8:$FE8,$BB$2:$FE$2,Q$2,$BB$1:$FE$1,Q$1) -> 0 | R8: =SUMIFS($BB8:$FE8,$BB$2:$FE$2,R$2,$BB$1:$FE$1,R$1) -> 0 | S8: =SUMIFS($BB8:$FE8,$BB$2:$FE$2,S$2,$BB$1:$FE$1,S$1) -> 0 | T8: =SUMIFS($BB8:$FE8,$BB$2:$FE$2,T$2,$BB$1:$FE$1,T$1) -> 0 | U8: =SUMIFS($BB8:$FE8,$BB$2:$FE$2,U$2,$BB$1:$FE$1,U$1) -> 0 | V8: =SUMIFS($BB8:$FE8,$BB$2:$FE$2,V$2,$BB$1:$FE$1,V$1) -> 0 | W8: =SUMIFS($BB8:$FE8,$BB$2:$FE$2,W$2,$BB$1:$FE$1,W$1) -> 0 | X8: =SUMIFS($BB8:$FE8,$BB$2:$FE$2,X$2,$BB$1:$FE$1,X$1) -> 0 | ... AZ8: =SUMIFS($BB8:$FE8,$BB$2:$FE$2,AZ$2,$BB$1:$FE$1,AZ$1) -> 0 | BB8: =SUM(BB15,BB22) -> 0 | BC8: =SUM(BC15,BC22) -> 0 | BD8: =SUM(BD15,BD22) -> 0 | BE8: =SUM(BE15,BE22) -> 0 | BF8: =SUM(BF15,BF22) -> 0 | BG8: =SUM(BG15,BG22) -> 0 | BH8: =SUM(BH15,BH22) -> 0 | BI8: =SUM(BI15,BI22) -> 0 | ... FE8: =SUM(FE15,FE22) -> 0
B9: объем законтрактованных площадей, м2 | D9: =C9=E9 -> TRUE | E9: =SUM(BB9:FE9) -> 0 | G9: =SUMIFS($BB9:$FE9,$BB$2:$FE$2,G$6) -> 0 | H9: =SUMIFS($BB9:$FE9,$BB$2:$FE$2,H$6) -> 0 | I9: =SUMIFS($BB9:$FE9,$BB$2:$FE$2,I$6) -> 0 | J9: =SUMIFS($BB9:$FE9,$BB$2:$FE$2,J$6) -> 0 | K9: =SUMIFS($BB9:$FE9,$BB$2:$FE$2,K$6) -> 0 | L9: =SUMIFS($BB9:$FE9,$BB$2:$FE$2,L$6) -> 0 | M9: =SUMIFS($BB9:$FE9,$BB$2:$FE$2,M$6) -> 0 | N9: =SUMIFS($BB9:$FE9,$BB$2:$FE$2,N$6) -> 0 | O9: =SUMIFS($BB9:$FE9,$BB$2:$FE$2,O$6) -> 0 | Q9: =SUMIFS($BB9:$FE9,$BB$2:$FE$2,Q$2,$BB$1:$FE$1,Q$1) -> 0 | R9: =SUMIFS($BB9:$FE9,$BB$2:$FE$2,R$2,$BB$1:$FE$1,R$1) -> 0 | S9: =SUMIFS($BB9:$FE9,$BB$2:$FE$2,S$2,$BB$1:$FE$1,S$1) -> 0 | T9: =SUMIFS($BB9:$FE9,$BB$2:$FE$2,T$2,$BB$1:$FE$1,T$1) -> 0 | U9: =SUMIFS($BB9:$FE9,$BB$2:$FE$2,U$2,$BB$1:$FE$1,U$1) -> 0 | V9: =SUMIFS($BB9:$FE9,$BB$2:$FE$2,V$2,$BB$1:$FE$1,V$1) -> 0 | W9: =SUMIFS($BB9:$FE9,$BB$2:$FE$2,W$2,$BB$1:$FE$1,W$1) -> 0 | X9: =SUMIFS($BB9:$FE9,$BB$2:$FE$2,X$2,$BB$1:$FE$1,X$1) -> 0 | ... AZ9: =SUMIFS($BB9:$FE9,$BB$2:$FE$2,AZ$2,$BB$1:$FE$1,AZ$1) -> 0 | BB9: =SUM(BB16,BB23) -> 0 | BC9: =SUM(BC16,BC23) -> 0 | BD9: =SUM(BD16,BD23) -> 0 | BE9: =SUM(BE16,BE23) -> 0 | BF9: =SUM(BF16,BF23) -> 0 | BG9: =SUM(BG16,BG23) -> 0 | BH9: =SUM(BH16,BH23) -> 0 | BI9: =SUM(BI16,BI23) -> 0 | ... FE9: =SUM(FE16,FE23) -> 0
B10: цена за 1 м2, руб. | E10: =IFERROR(E8/E9,0) -> 0 | G10: =IFERROR(G8/G9,0) -> 0 | H10: =IFERROR(H8/H9,0) -> 0 | I10: =IFERROR(I8/I9,0) -> 0 | J10: =IFERROR(J8/J9,0) -> 0 | K10: =IFERROR(K8/K9,0) -> 0 | L10: =IFERROR(L8/L9,0) -> 0 | M10: =IFERROR(M8/M9,0) -> 0 | N10: =IFERROR(N8/N9,0) -> 0 | O10: =IFERROR(O8/O9,0) -> 0 | Q10: =IFERROR(Q8/Q9,0) -> 0 | R10: =IFERROR(R8/R9,0) -> 0 | S10: =IFERROR(S8/S9,0) -> 0 | T10: =IFERROR(T8/T9,0) -> 0 | U10: =IFERROR(U8/U9,0) -> 0 | V10: =IFERROR(V8/V9,0) -> 0 | W10: =IFERROR(W8/W9,0) -> 0 | X10: =IFERROR(X8/X9,0) -> 0 | ... AZ10: =IFERROR(AZ8/AZ9,0) -> 0 | BB10: =IFERROR(BB8/BB9,0) -> 0 | BC10: =IFERROR(BC8/BC9,0) -> 0 | BD10: =IFERROR(BD8/BD9,0) -> 0 | BE10: =IFERROR(BE8/BE9,0) -> 0 | BF10: =IFERROR(BF8/BF9,0) -> 0 | BG10: =IFERROR(BG8/BG9,0) -> 0 | BH10: =IFERROR(BH8/BH9,0) -> 0 | BI10: =IFERROR(BI8/BI9,0) -> 0 | ... FE10: =IFERROR(FE8/FE9,0) -> 0
B11: объем законтрактованных площадей, шт | D11: =C11=E11 -> TRUE | E11: =SUM(BB11:FE11) -> 0 | G11: =SUMIFS($BB11:$FE11,$BB$2:$FE$2,G$6) -> 0 | H11: =SUMIFS($BB11:$FE11,$BB$2:$FE$2,H$6) -> 0 | I11: =SUMIFS($BB11:$FE11,$BB$2:$FE$2,I$6) -> 0 | J11: =SUMIFS($BB11:$FE11,$BB$2:$FE$2,J$6) -> 0 | K11: =SUMIFS($BB11:$FE11,$BB$2:$FE$2,K$6) -> 0 | L11: =SUMIFS($BB11:$FE11,$BB$2:$FE$2,L$6) -> 0 | M11: =SUMIFS($BB11:$FE11,$BB$2:$FE$2,M$6) -> 0 | N11: =SUMIFS($BB11:$FE11,$BB$2:$FE$2,N$6) -> 0 | O11: =SUMIFS($BB11:$FE11,$BB$2:$FE$2,O$6) -> 0 | Q11: =SUMIFS($BB11:$FE11,$BB$2:$FE$2,Q$2,$BB$1:$FE$1,Q$1) -> 0 | R11: =SUMIFS($BB11:$FE11,$BB$2:$FE$2,R$2,$BB$1:$FE$1,R$1) -> 0 | S11: =SUMIFS($BB11:$FE11,$BB$2:$FE$2,S$2,$BB$1:$FE$1,S$1) -> 0 | T11: =SUMIFS($BB11:$FE11,$BB$2:$FE$2,T$2,$BB$1:$FE$1,T$1) -> 0 | U11: =SUMIFS($BB11:$FE11,$BB$2:$FE$2,U$2,$BB$1:$FE$1,U$1) -> 0 | V11: =SUMIFS($BB11:$FE11,$BB$2:$FE$2,V$2,$BB$1:$FE$1,V$1) -> 0 | W11: =SUMIFS($BB11:$FE11,$BB$2:$FE$2,W$2,$BB$1:$FE$1,W$1) -> 0 | X11: =SUMIFS($BB11:$FE11,$BB$2:$FE$2,X$2,$BB$1:$FE$1,X$1) -> 0 | ... AZ11: =SUMIFS($BB11:$FE11,$BB$2:$FE$2,AZ$2,$BB$1:$FE$1,AZ$1) -> 0 | BB11: =SUM(BB18,BB25) -> 0 | BC11: =SUM(BC18,BC25) -> 0 | BD11: =SUM(BD18,BD25) -> 0 | BE11: =SUM(BE18,BE25) -> 0 | BF11: =SUM(BF18,BF25) -> 0 | BG11: =SUM(BG18,BG25) -> 0 | BH11: =SUM(BH18,BH25) -> 0 | BI11: =SUM(BI18,BI25) -> 0 | ... FE11: =SUM(FE18,FE25) -> 0
B12: Поступление ден. средств, руб. | E12: =SUM(BB12:FE12) -> 0 | G12: =SUMIFS($BB12:$FE12,$BB$2:$FE$2,G$6) -> 0 | H12: =SUMIFS($BB12:$FE12,$BB$2:$FE$2,H$6) -> 0 | I12: =SUMIFS($BB12:$FE12,$BB$2:$FE$2,I$6) -> 0 | J12: =SUMIFS($BB12:$FE12,$BB$2:$FE$2,J$6) -> 0 | K12: =SUMIFS($BB12:$FE12,$BB$2:$FE$2,K$6) -> 0 | L12: =SUMIFS($BB12:$FE12,$BB$2:$FE$2,L$6) -> 0 | M12: =SUMIFS($BB12:$FE12,$BB$2:$FE$2,M$6) -> 0 | N12: =SUMIFS($BB12:$FE12,$BB$2:$FE$2,N$6) -> 0 | O12: =SUMIFS($BB12:$FE12,$BB$2:$FE$2,O$6) -> 0 | Q12: =SUMIFS($BB12:$FE12,$BB$2:$FE$2,Q$2,$BB$1:$FE$1,Q$1) -> 0 | R12: =SUMIFS($BB12:$FE12,$BB$2:$FE$2,R$2,$BB$1:$FE$1,R$1) -> 0 | S12: =SUMIFS($BB12:$FE12,$BB$2:$FE$2,S$2,$BB$1:$FE$1,S$1) -> 0 | T12: =SUMIFS($BB12:$FE12,$BB$2:$FE$2,T$2,$BB$1:$FE$1,T$1) -> 0 | U12: =SUMIFS($BB12:$FE12,$BB$2:$FE$2,U$2,$BB$1:$FE$1,U$1) -> 0 | V12: =SUMIFS($BB12:$FE12,$BB$2:$FE$2,V$2,$BB$1:$FE$1,V$1) -> 0 | W12: =SUMIFS($BB12:$FE12,$BB$2:$FE$2,W$2,$BB$1:$FE$1,W$1) -> 0 | X12: =SUMIFS($BB12:$FE12,$BB$2:$FE$2,X$2,$BB$1:$FE$1,X$1) -> 0 | ... AZ12: =SUMIFS($BB12:$FE12,$BB$2:$FE$2,AZ$2,$BB$1:$FE$1,AZ$1) -> 0 | BB12: =SUM(BB19,BB26) -> 0 | BC12: =SUM(BC19,BC26) -> 0 | BD12: =SUM(BD19,BD26) -> 0 | BE12: =SUM(BE19,BE26) -> 0 | BF12: =SUM(BF19,BF26) -> 0 | BG12: =SUM(BG19,BG26) -> 0 | BH12: =SUM(BH19,BH26) -> 0 | BI12: =SUM(BI19,BI26) -> 0 | ... FE12: =SUM(FE19,FE26) -> 0
B14: ПРОДАНО
B15: Продажи, руб. | D15: =E15=E19 -> TRUE | E15: =SUM(BB15:FE15) -> 0 | G15: =SUMIFS($BB15:$FE15,$BB$2:$FE$2,G$6) -> 0 | H15: =SUMIFS($BB15:$FE15,$BB$2:$FE$2,H$6) -> 0 | I15: =SUMIFS($BB15:$FE15,$BB$2:$FE$2,I$6) -> 0 | J15: =SUMIFS($BB15:$FE15,$BB$2:$FE$2,J$6) -> 0 | K15: =SUMIFS($BB15:$FE15,$BB$2:$FE$2,K$6) -> 0 | L15: =SUMIFS($BB15:$FE15,$BB$2:$FE$2,L$6) -> 0 | M15: =SUMIFS($BB15:$FE15,$BB$2:$FE$2,M$6) -> 0 | N15: =SUMIFS($BB15:$FE15,$BB$2:$FE$2,N$6) -> 0 | O15: =SUMIFS($BB15:$FE15,$BB$2:$FE$2,O$6) -> 0 | Q15: =SUMIFS($BB15:$FE15,$BB$2:$FE$2,Q$2,$BB$1:$FE$1,Q$1) -> 0 | R15: =SUMIFS($BB15:$FE15,$BB$2:$FE$2,R$2,$BB$1:$FE$1,R$1) -> 0 | S15: =SUMIFS($BB15:$FE15,$BB$2:$FE$2,S$2,$BB$1:$FE$1,S$1) -> 0 | T15: =SUMIFS($BB15:$FE15,$BB$2:$FE$2,T$2,$BB$1:$FE$1,T$1) -> 0 | U15: =SUMIFS($BB15:$FE15,$BB$2:$FE$2,U$2,$BB$1:$FE$1,U$1) -> 0 | V15: =SUMIFS($BB15:$FE15,$BB$2:$FE$2,V$2,$BB$1:$FE$1,V$1) -> 0 | W15: =SUMIFS($BB15:$FE15,$BB$2:$FE$2,W$2,$BB$1:$FE$1,W$1) -> 0 | X15: =SUMIFS($BB15:$FE15,$BB$2:$FE$2,X$2,$BB$1:$FE$1,X$1) -> 0 | ... AZ15: =SUMIFS($BB15:$FE15,$BB$2:$FE$2,AZ$2,$BB$1:$FE$1,AZ$1) -> 0
B16: объем законтрактованных площадей, м2 | D16: =C16=E16 -> TRUE | E16: =SUM(BB16:FE16) -> 0 | G16: =SUMIFS($BB16:$FE16,$BB$2:$FE$2,G$6) -> 0 | H16: =SUMIFS($BB16:$FE16,$BB$2:$FE$2,H$6) -> 0 | I16: =SUMIFS($BB16:$FE16,$BB$2:$FE$2,I$6) -> 0 | J16: =SUMIFS($BB16:$FE16,$BB$2:$FE$2,J$6) -> 0 | K16: =SUMIFS($BB16:$FE16,$BB$2:$FE$2,K$6) -> 0 | L16: =SUMIFS($BB16:$FE16,$BB$2:$FE$2,L$6) -> 0 | M16: =SUMIFS($BB16:$FE16,$BB$2:$FE$2,M$6) -> 0 | N16: =SUMIFS($BB16:$FE16,$BB$2:$FE$2,N$6) -> 0 | O16: =SUMIFS($BB16:$FE16,$BB$2:$FE$2,O$6) -> 0 | Q16: =SUMIFS($BB16:$FE16,$BB$2:$FE$2,Q$2,$BB$1:$FE$1,Q$1) -> 0 | R16: =SUMIFS($BB16:$FE16,$BB$2:$FE$2,R$2,$BB$1:$FE$1,R$1) -> 0 | S16: =SUMIFS($BB16:$FE16,$BB$2:$FE$2,S$2,$BB$1:$FE$1,S$1) -> 0 | T16: =SUMIFS($BB16:$FE16,$BB$2:$FE$2,T$2,$BB$1:$FE$1,T$1) -> 0 | U16: =SUMIFS($BB16:$FE16,$BB$2:$FE$2,U$2,$BB$1:$FE$1,U$1) -> 0 | V16: =SUMIFS($BB16:$FE16,$BB$2:$FE$2,V$2,$BB$1:$FE$1,V$1) -> 0 | W16: =SUMIFS($BB16:$FE16,$BB$2:$FE$2,W$2,$BB$1:$FE$1,W$1) -> 0 | X16: =SUMIFS($BB16:$FE16,$BB$2:$FE$2,X$2,$BB$1:$FE$1,X$1) -> 0 | ... AZ16: =SUMIFS($BB16:$FE16,$BB$2:$FE$2,AZ$2,$BB$1:$FE$1,AZ$1) -> 0
B17: цена за 1 м2, руб. | E17: =IFERROR(E15/E16,0) -> 0 | G17: =IFERROR(G15/G16,0) -> 0 | H17: =IFERROR(H15/H16,0) -> 0 | I17: =IFERROR(I15/I16,0) -> 0 | J17: =IFERROR(J15/J16,0) -> 0 | K17: =IFERROR(K15/K16,0) -> 0 | L17: =IFERROR(L15/L16,0) -> 0 | M17: =IFERROR(M15/M16,0) -> 0 | N17: =IFERROR(N15/N16,0) -> 0 | O17: =IFERROR(O15/O16,0) -> 0 | Q17: =IFERROR(Q15/Q16,0) -> 0 | R17: =IFERROR(R15/R16,0) -> 0 | S17: =IFERROR(S15/S16,0) -> 0 | T17: =IFERROR(T15/T16,0) -> 0 | U17: =IFERROR(U15/U16,0) -> 0 | V17: =IFERROR(V15/V16,0) -> 0 | W17: =IFERROR(W15/W16,0) -> 0 | X17: =IFERROR(X15/X16,0) -> 0 | ... AZ17: =IFERROR(AZ15/AZ16,0) -> 0
B18: объем законтрактованных площадей, шт | D18: =C18=E18 -> TRUE | E18: =SUM(BB18:FE18) -> 0 | G18: =SUMIFS($BB18:$FE18,$BB$2:$FE$2,G$6) -> 0 | H18: =SUMIFS($BB18:$FE18,$BB$2:$FE$2,H$6) -> 0 | I18: =SUMIFS($BB18:$FE18,$BB$2:$FE$2,I$6) -> 0 | J18: =SUMIFS($BB18:$FE18,$BB$2:$FE$2,J$6) -> 0 | K18: =SUMIFS($BB18:$FE18,$BB$2:$FE$2,K$6) -> 0 | L18: =SUMIFS($BB18:$FE18,$BB$2:$FE$2,L$6) -> 0 | M18: =SUMIFS($BB18:$FE18,$BB$2:$FE$2,M$6) -> 0 | N18: =SUMIFS($BB18:$FE18,$BB$2:$FE$2,N$6) -> 0 | O18: =SUMIFS($BB18:$FE18,$BB$2:$FE$2,O$6) -> 0 | Q18: =SUMIFS($BB18:$FE18,$BB$2:$FE$2,Q$2,$BB$1:$FE$1,Q$1) -> 0 | R18: =SUMIFS($BB18:$FE18,$BB$2:$FE$2,R$2,$BB$1:$FE$1,R$1) -> 0 | S18: =SUMIFS($BB18:$FE18,$BB$2:$FE$2,S$2,$BB$1:$FE$1,S$1) -> 0 | T18: =SUMIFS($BB18:$FE18,$BB$2:$FE$2,T$2,$BB$1:$FE$1,T$1) -> 0 | U18: =SUMIFS($BB18:$FE18,$BB$2:$FE$2,U$2,$BB$1:$FE$1,U$1) -> 0 | V18: =SUMIFS($BB18:$FE18,$BB$2:$FE$2,V$2,$BB$1:$FE$1,V$1) -> 0 | W18: =SUMIFS($BB18:$FE18,$BB$2:$FE$2,W$2,$BB$1:$FE$1,W$1) -> 0 | X18: =SUMIFS($BB18:$FE18,$BB$2:$FE$2,X$2,$BB$1:$FE$1,X$1) -> 0 | ... AZ18: =SUMIFS($BB18:$FE18,$BB$2:$FE$2,AZ$2,$BB$1:$FE$1,AZ$1) -> 0
B19: Поступление ден. средств, руб. | E19: =SUM(BB19:FE19) -> 0 | G19: =SUMIFS($BB19:$FE19,$BB$2:$FE$2,G$6) -> 0 | H19: =SUMIFS($BB19:$FE19,$BB$2:$FE$2,H$6) -> 0 | I19: =SUMIFS($BB19:$FE19,$BB$2:$FE$2,I$6) -> 0 | J19: =SUMIFS($BB19:$FE19,$BB$2:$FE$2,J$6) -> 0 | K19: =SUMIFS($BB19:$FE19,$BB$2:$FE$2,K$6) -> 0 | L19: =SUMIFS($BB19:$FE19,$BB$2:$FE$2,L$6) -> 0 | M19: =SUMIFS($BB19:$FE19,$BB$2:$FE$2,M$6) -> 0 | N19: =SUMIFS($BB19:$FE19,$BB$2:$FE$2,N$6) -> 0 | O19: =SUMIFS($BB19:$FE19,$BB$2:$FE$2,O$6) -> 0 | Q19: =SUMIFS($BB19:$FE19,$BB$2:$FE$2,Q$2,$BB$1:$FE$1,Q$1) -> 0 | R19: =SUMIFS($BB19:$FE19,$BB$2:$FE$2,R$2,$BB$1:$FE$1,R$1) -> 0 | S19: =SUMIFS($BB19:$FE19,$BB$2:$FE$2,S$2,$BB$1:$FE$1,S$1) -> 0 | T19: =SUMIFS($BB19:$FE19,$BB$2:$FE$2,T$2,$BB$1:$FE$1,T$1) -> 0 | U19: =SUMIFS($BB19:$FE19,$BB$2:$FE$2,U$2,$BB$1:$FE$1,U$1) -> 0 | V19: =SUMIFS($BB19:$FE19,$BB$2:$FE$2,V$2,$BB$1:$FE$1,V$1) -> 0 | W19: =SUMIFS($BB19:$FE19,$BB$2:$FE$2,W$2,$BB$1:$FE$1,W$1) -> 0 | X19: =SUMIFS($BB19:$FE19,$BB$2:$FE$2,X$2,$BB$1:$FE$1,X$1) -> 0 | ... AZ19: =SUMIFS($BB19:$FE19,$BB$2:$FE$2,AZ$2,$BB$1:$FE$1,AZ$1) -> 0
B21: ОСТАТОК К ПРОДАЖЕ
B22: Продажи, руб. | D22: =E22=E26 -> TRUE | E22: =SUM(BB22:FE22) -> 0 | G22: =SUMIFS($BB22:$FE22,$BB$2:$FE$2,G$6) -> 0 | H22: =SUMIFS($BB22:$FE22,$BB$2:$FE$2,H$6) -> 0 | I22: =SUMIFS($BB22:$FE22,$BB$2:$FE$2,I$6) -> 0 | J22: =SUMIFS($BB22:$FE22,$BB$2:$FE$2,J$6) -> 0 | K22: =SUMIFS($BB22:$FE22,$BB$2:$FE$2,K$6) -> 0 | L22: =SUMIFS($BB22:$FE22,$BB$2:$FE$2,L$6) -> 0 | M22: =SUMIFS($BB22:$FE22,$BB$2:$FE$2,M$6) -> 0 | N22: =SUMIFS($BB22:$FE22,$BB$2:$FE$2,N$6) -> 0 | O22: =SUMIFS($BB22:$FE22,$BB$2:$FE$2,O$6) -> 0 | Q22: =SUMIFS($BB22:$FE22,$BB$2:$FE$2,Q$2,$BB$1:$FE$1,Q$1) -> 0 | R22: =SUMIFS($BB22:$FE22,$BB$2:$FE$2,R$2,$BB$1:$FE$1,R$1) -> 0 | S22: =SUMIFS($BB22:$FE22,$BB$2:$FE$2,S$2,$BB$1:$FE$1,S$1) -> 0 | T22: =SUMIFS($BB22:$FE22,$BB$2:$FE$2,T$2,$BB$1:$FE$1,T$1) -> 0 | U22: =SUMIFS($BB22:$FE22,$BB$2:$FE$2,U$2,$BB$1:$FE$1,U$1) -> 0 | V22: =SUMIFS($BB22:$FE22,$BB$2:$FE$2,V$2,$BB$1:$FE$1,V$1) -> 0 | W22: =SUMIFS($BB22:$FE22,$BB$2:$FE$2,W$2,$BB$1:$FE$1,W$1) -> 0 | X22: =SUMIFS($BB22:$FE22,$BB$2:$FE$2,X$2,$BB$1:$FE$1,X$1) -> 0 | ... AZ22: =SUMIFS($BB22:$FE22,$BB$2:$FE$2,AZ$2,$BB$1:$FE$1,AZ$1) -> 0
B23: объем законтрактованных площадей, м2 | D23: =C23=E23 -> TRUE | E23: =SUM(BB23:FE23) -> 0 | G23: =SUMIFS($BB23:$FE23,$BB$2:$FE$2,G$6) -> 0 | H23: =SUMIFS($BB23:$FE23,$BB$2:$FE$2,H$6) -> 0 | I23: =SUMIFS($BB23:$FE23,$BB$2:$FE$2,I$6) -> 0 | J23: =SUMIFS($BB23:$FE23,$BB$2:$FE$2,J$6) -> 0 | K23: =SUMIFS($BB23:$FE23,$BB$2:$FE$2,K$6) -> 0 | L23: =SUMIFS($BB23:$FE23,$BB$2:$FE$2,L$6) -> 0 | M23: =SUMIFS($BB23:$FE23,$BB$2:$FE$2,M$6) -> 0 | N23: =SUMIFS($BB23:$FE23,$BB$2:$FE$2,N$6) -> 0 | O23: =SUMIFS($BB23:$FE23,$BB$2:$FE$2,O$6) -> 0 | Q23: =SUMIFS($BB23:$FE23,$BB$2:$FE$2,Q$2,$BB$1:$FE$1,Q$1) -> 0 | R23: =SUMIFS($BB23:$FE23,$BB$2:$FE$2,R$2,$BB$1:$FE$1,R$1) -> 0 | S23: =SUMIFS($BB23:$FE23,$BB$2:$FE$2,S$2,$BB$1:$FE$1,S$1) -> 0 | T23: =SUMIFS($BB23:$FE23,$BB$2:$FE$2,T$2,$BB$1:$FE$1,T$1) -> 0 | U23: =SUMIFS($BB23:$FE23,$BB$2:$FE$2,U$2,$BB$1:$FE$1,U$1) -> 0 | V23: =SUMIFS($BB23:$FE23,$BB$2:$FE$2,V$2,$BB$1:$FE$1,V$1) -> 0 | W23: =SUMIFS($BB23:$FE23,$BB$2:$FE$2,W$2,$BB$1:$FE$1,W$1) -> 0 | X23: =SUMIFS($BB23:$FE23,$BB$2:$FE$2,X$2,$BB$1:$FE$1,X$1) -> 0 | ... AZ23: =SUMIFS($BB23:$FE23,$BB$2:$FE$2,AZ$2,$BB$1:$FE$1,AZ$1) -> 0
B24: цена за 1 м2, руб. | E24: =IFERROR(E22/E23,0) -> 0 | G24: =IFERROR(G22/G23,0) -> 0 | H24: =IFERROR(H22/H23,0) -> 0 | I24: =IFERROR(I22/I23,0) -> 0 | J24: =IFERROR(J22/J23,0) -> 0 | K24: =IFERROR(K22/K23,0) -> 0 | L24: =IFERROR(L22/L23,0) -> 0 | M24: =IFERROR(M22/M23,0) -> 0 | N24: =IFERROR(N22/N23,0) -> 0 | O24: =IFERROR(O22/O23,0) -> 0 | Q24: =IFERROR(Q22/Q23,0) -> 0 | R24: =IFERROR(R22/R23,0) -> 0 | S24: =IFERROR(S22/S23,0) -> 0 | T24: =IFERROR(T22/T23,0) -> 0 | U24: =IFERROR(U22/U23,0) -> 0 | V24: =IFERROR(V22/V23,0) -> 0 | W24: =IFERROR(W22/W23,0) -> 0 | X24: =IFERROR(X22/X23,0) -> 0 | ... AZ24: =IFERROR(AZ22/AZ23,0) -> 0
B25: объем законтрактованных площадей, шт | D25: =C25=E25 -> TRUE | E25: =SUM(BB25:FE25) -> 0 | G25: =SUMIFS($BB25:$FE25,$BB$2:$FE$2,G$6) -> 0 | H25: =SUMIFS($BB25:$FE25,$BB$2:$FE$2,H$6) -> 0 | I25: =SUMIFS($BB25:$FE25,$BB$2:$FE$2,I$6) -> 0 | J25: =SUMIFS($BB25:$FE25,$BB$2:$FE$2,J$6) -> 0 | K25: =SUMIFS($BB25:$FE25,$BB$2:$FE$2,K$6) -> 0 | L25: =SUMIFS($BB25:$FE25,$BB$2:$FE$2,L$6) -> 0 | M25: =SUMIFS($BB25:$FE25,$BB$2:$FE$2,M$6) -> 0 | N25: =SUMIFS($BB25:$FE25,$BB$2:$FE$2,N$6) -> 0 | O25: =SUMIFS($BB25:$FE25,$BB$2:$FE$2,O$6) -> 0 | Q25: =SUMIFS($BB25:$FE25,$BB$2:$FE$2,Q$2,$BB$1:$FE$1,Q$1) -> 0 | R25: =SUMIFS($BB25:$FE25,$BB$2:$FE$2,R$2,$BB$1:$FE$1,R$1) -> 0 | S25: =SUMIFS($BB25:$FE25,$BB$2:$FE$2,S$2,$BB$1:$FE$1,S$1) -> 0 | T25: =SUMIFS($BB25:$FE25,$BB$2:$FE$2,T$2,$BB$1:$FE$1,T$1) -> 0 | U25: =SUMIFS($BB25:$FE25,$BB$2:$FE$2,U$2,$BB$1:$FE$1,U$1) -> 0 | V25: =SUMIFS($BB25:$FE25,$BB$2:$FE$2,V$2,$BB$1:$FE$1,V$1) -> 0 | W25: =SUMIFS($BB25:$FE25,$BB$2:$FE$2,W$2,$BB$1:$FE$1,W$1) -> 0 | X25: =SUMIFS($BB25:$FE25,$BB$2:$FE$2,X$2,$BB$1:$FE$1,X$1) -> 0 | ... AZ25: =SUMIFS($BB25:$FE25,$BB$2:$FE$2,AZ$2,$BB$1:$FE$1,AZ$1) -> 0
B26: Поступление ден. средств, руб. | E26: =SUM(BB26:FE26) -> 0 | G26: =SUMIFS($BB26:$FE26,$BB$2:$FE$2,G$6) -> 0 | H26: =SUMIFS($BB26:$FE26,$BB$2:$FE$2,H$6) -> 0 | I26: =SUMIFS($BB26:$FE26,$BB$2:$FE$2,I$6) -> 0 | J26: =SUMIFS($BB26:$FE26,$BB$2:$FE$2,J$6) -> 0 | K26: =SUMIFS($BB26:$FE26,$BB$2:$FE$2,K$6) -> 0 | L26: =SUMIFS($BB26:$FE26,$BB$2:$FE$2,L$6) -> 0 | M26: =SUMIFS($BB26:$FE26,$BB$2:$FE$2,M$6) -> 0 | N26: =SUMIFS($BB26:$FE26,$BB$2:$FE$2,N$6) -> 0 | O26: =SUMIFS($BB26:$FE26,$BB$2:$FE$2,O$6) -> 0 | Q26: =SUMIFS($BB26:$FE26,$BB$2:$FE$2,Q$2,$BB$1:$FE$1,Q$1) -> 0 | R26: =SUMIFS($BB26:$FE26,$BB$2:$FE$2,R$2,$BB$1:$FE$1,R$1) -> 0 | S26: =SUMIFS($BB26:$FE26,$BB$2:$FE$2,S$2,$BB$1:$FE$1,S$1) -> 0 | T26: =SUMIFS($BB26:$FE26,$BB$2:$FE$2,T$2,$BB$1:$FE$1,T$1) -> 0 | U26: =SUMIFS($BB26:$FE26,$BB$2:$FE$2,U$2,$BB$1:$FE$1,U$1) -> 0 | V26: =SUMIFS($BB26:$FE26,$BB$2:$FE$2,V$2,$BB$1:$FE$1,V$1) -> 0 | W26: =SUMIFS($BB26:$FE26,$BB$2:$FE$2,W$2,$BB$1:$FE$1,W$1) -> 0 | X26: =SUMIFS($BB26:$FE26,$BB$2:$FE$2,X$2,$BB$1:$FE$1,X$1) -> 0 | ... AZ26: =SUMIFS($BB26:$FE26,$BB$2:$FE$2,AZ$2,$BB$1:$FE$1,AZ$1) -> 0

Sheet АПАРТЫ
B1: Вспомогательная строка (для суммирования) | Q1: 1 кв | R1: 2 кв | S1: 3 кв | T1: 4 кв | U1: 1 кв | V1: 2 кв | W1: 3 кв | X1: 4 кв | Y1: 1 кв | Z1: 2 кв | AA1: 3 кв | AB1: 4 кв | AC1: 1 кв | AD1: 2 кв | AE1: 3 кв | AF1: 4 кв | AG1: 1 кв | AH1: 2 кв | AI1: 3 кв | AJ1: 4 кв | AK1: 1 кв | AL1: 2 кв | AM1: 3 кв | AN1: 4 кв | AO1: 1 кв | AP1: 2 кв | AQ1: 3 кв | AR1: 4 кв | AS1: 1 кв | AT1: 2 кв | AU1: 3 кв | AV1: 4 кв | AW1: 1 кв | AX1: 2 кв | AY1: 3 кв | AZ1: 4 кв | BB1: 1 кв | BC1: 1 кв | BD1: 1 кв | BE1: 2 кв | BF1: 2 кв | BG1: 2 кв | BH1: 3 кв | BI1: 3 кв | BJ1: 3 кв | BK1: 4 кв | BL1: 4 кв | BM1: 4 кв | BN1: 1 кв | BO1: 1 кв | BP1: 1 кв | BQ1: 2 кв | BR1: 2 кв | BS1: 2 кв | BT1: 3 кв | BU1: 3 кв | BV1: 3 кв | BW1: 4 кв | BX1: 4 кв | BY1: 4 кв | BZ1: 1 кв | CA1: 1 кв | CB1: 1 кв | CC1: 2 кв | CD1: 2 кв | CE1: 2 кв | CF1: 3 кв | CG1: 3 кв | CH1: 3 кв | CI1: 4 кв | CJ1: 4 кв | CK1: 4 кв | CL1: 1 кв | CM1: 1 кв | CN1: 1 кв | CO1: 2 кв | CP1: 2 кв | CQ1: 2 кв | CR1: 3 кв | CS1: 3 кв | CT1: 3 кв | CU1: 4 кв | CV1: 4 кв | CW1: 4 кв | CX1: 1 кв | CY1: 1 кв | CZ1: 1 кв | DA1: 2 кв | DB1: 2 кв | DC1: 2 кв | DD1: 3 кв | DE1: 3 кв | DF1: 3 кв | DG1: 4 кв | DH1: 4 кв | DI1: 4 кв | DJ1: 1 кв | DK1: 1 кв | DL1: 1 кв | DM1: 2 кв | DN1: 2 кв | DO1: 2 кв | DP1: 3 кв | DQ1: 3 кв | DR1: 3 кв | DS1: 4 кв | DT1: 4 кв | DU1: 4 кв | DV1: 1 кв | DW1: 1 кв | DX1: 1 кв | DY1: 2 кв | DZ1: 2 кв | EA1: 2 кв | EB1: 3 кв | EC1: 3 кв | ED1: 3 кв | EE1: 4 кв | EF1: 4 кв | EG1: 4 кв | EH1: 1 кв | EI1: 1 кв | EJ1: 1 кв | EK1: 2 кв | EL1: 2 кв | EM1: 2 кв | EN1: 3 кв | EO1: 3 кв | EP1: 3 кв | EQ1: 4 кв | ER1: 4 кв | ES1: 4 кв | ET1: 1 кв | EU1: 1 кв | EV1: 1 кв | EW1: 2 кв | EX1: 2 кв | EY1: 2 кв | EZ1: 3 кв | FA1: 3 кв | FB1: 3 кв | FC1: 4 кв | FD1: 4 кв | FE1: 4 кв
B2: Вспомогательная строка (для суммирования) | Q2: 2025 | R2: 2025 | S2: 2025 | T2: 2025 | U2: 2026 | V2: 2026 | W2: 2026 | X2: 2026 | Y2: 2027 | Z2: 2027 | AA2: 2027 | AB2: 2027 | AC2: 2028 | AD2: 2028 | AE2: 2028 | AF2: 2028 | AG2: 2029 | AH2: 2029 | AI2: 2029 | AJ2: 2029 | AK2: 2030 | AL2: 2030 | AM2: 2030 | AN2: 2030 | AO2: 2031 | AP2: 2031 | AQ2: 2031 | AR2: 2031 | AS2: 2032 | AT2: 2032 | AU2: 2032 | AV2: 2032 | AW2: 2033 | AX2: 2033 | AY2: 2033 | AZ2: 2033 | BB2: =YEAR(BB6) -> 2025 | BC2: =YEAR(BC6) -> 2025 | BD2: =YEAR(BD6) -> 2025 | BE2: =YEAR(BE6) -> 2025 | BF2: =YEAR(BF6) -> 2025 | BG2: =YEAR(BG6) -> 2025 | BH2: =YEAR(BH6) -> 2025 | BI2: =YEAR(BI6) -> 2025 | ... FE2: =YEAR(FE6) -> 2033
